WARNING 2025-08-02 10:57:47,557 log Not Found: /
WARNING 2025-08-02 10:57:48,165 log Not Found: /
ERROR 2025-08-02 10:57:51,079 log Internal Server Error: /swagger/
Traceback (most recent call last):
  File "/usr/local/lib/python3.12/site-packages/django/contrib/sessions/backends/base.py", line 244, in _get_session
    return self._session_cache
           ^^^^^^^^^^^^^^^^^^^
AttributeError: 'SessionStore' object has no attribute '_session_cache'

During handling of the above exception, another exception occurred:

Traceback (most recent call last):
  File "/usr/local/lib/python3.12/site-packages/django/db/backends/utils.py", line 105, in _execute
    return self.cursor.execute(sql, params)
           ^^^^^^^^^^^^^^^^^^^^^^^^^^^^^^^^
psycopg2.errors.UndefinedTable: relation "django_session" does not exist
LINE 1: ...ession_data", "django_session"."expire_date" FROM "django_se...
                                                             ^


The above exception was the direct cause of the following exception:

Traceback (most recent call last):
  File "/usr/local/lib/python3.12/site-packages/asgiref/sync.py", line 489, in thread_handler
    raise exc_info[1]
  File "/usr/local/lib/python3.12/site-packages/django/core/handlers/exception.py", line 42, in inner
    response = await get_response(request)
               ^^^^^^^^^^^^^^^^^^^^^^^^^^^
  File "/usr/local/lib/python3.12/site-packages/asgiref/sync.py", line 489, in thread_handler
    raise exc_info[1]
  File "/usr/local/lib/python3.12/site-packages/django/core/handlers/base.py", line 253, in _get_response_async
    response = await wrapped_callback(
               ^^^^^^^^^^^^^^^^^^^^^^^
  File "/usr/local/lib/python3.12/site-packages/asgiref/sync.py", line 439, in __call__
    ret = await asyncio.shield(exec_coro)
          ^^^^^^^^^^^^^^^^^^^^^^^^^^^^^^^
  File "/usr/local/lib/python3.12/concurrent/futures/thread.py", line 59, in run
    result = self.fn(*self.args, **self.kwargs)
             ^^^^^^^^^^^^^^^^^^^^^^^^^^^^^^^^^^
  File "/usr/local/lib/python3.12/site-packages/asgiref/sync.py", line 493, in thread_handler
    return func(*args, **kwargs)
           ^^^^^^^^^^^^^^^^^^^^^
  File "/usr/local/lib/python3.12/site-packages/django/views/decorators/csrf.py", line 65, in _view_wrapper
    return view_func(request, *args, **kwargs)
           ^^^^^^^^^^^^^^^^^^^^^^^^^^^^^^^^^^^
  File "/usr/local/lib/python3.12/site-packages/django/views/generic/base.py", line 104, in view
    return self.dispatch(request, *args, **kwargs)
           ^^^^^^^^^^^^^^^^^^^^^^^^^^^^^^^^^^^^^^^
  File "/usr/local/lib/python3.12/site-packages/rest_framework/views.py", line 515, in dispatch
    response = self.handle_exception(exc)
               ^^^^^^^^^^^^^^^^^^^^^^^^^^
  File "/usr/local/lib/python3.12/site-packages/rest_framework/views.py", line 475, in handle_exception
    self.raise_uncaught_exception(exc)
  File "/usr/local/lib/python3.12/site-packages/rest_framework/views.py", line 486, in raise_uncaught_exception
    raise exc
  File "/usr/local/lib/python3.12/site-packages/rest_framework/views.py", line 503, in dispatch
    self.initial(request, *args, **kwargs)
  File "/usr/local/lib/python3.12/site-packages/rest_framework/views.py", line 420, in initial
    self.perform_authentication(request)
  File "/usr/local/lib/python3.12/site-packages/rest_framework/views.py", line 330, in perform_authentication
    request.user
  File "/usr/local/lib/python3.12/site-packages/rest_framework/request.py", line 232, in user
    self._authenticate()
  File "/usr/local/lib/python3.12/site-packages/rest_framework/request.py", line 385, in _authenticate
    user_auth_tuple = authenticator.authenticate(self)
                      ^^^^^^^^^^^^^^^^^^^^^^^^^^^^^^^^
  File "/usr/local/lib/python3.12/site-packages/rest_framework/authentication.py", line 127, in authenticate
    if not user or not user.is_active:
           ^^^^
  File "/usr/local/lib/python3.12/site-packages/django/utils/functional.py", line 251, in inner
    self._setup()
  File "/usr/local/lib/python3.12/site-packages/django/utils/functional.py", line 404, in _setup
    self._wrapped = self._setupfunc()
                    ^^^^^^^^^^^^^^^^^
  File "/usr/local/lib/python3.12/site-packages/django/contrib/auth/middleware.py", line 39, in <lambda>
    request.user = SimpleLazyObject(lambda: get_user(request))
                                            ^^^^^^^^^^^^^^^^^
  File "/usr/local/lib/python3.12/site-packages/django/contrib/auth/middleware.py", line 19, in get_user
    request._cached_user = auth.get_user(request)
                           ^^^^^^^^^^^^^^^^^^^^^^
  File "/usr/local/lib/python3.12/site-packages/django/contrib/auth/__init__.py", line 304, in get_user
    user_id = _get_user_session_key(request)
              ^^^^^^^^^^^^^^^^^^^^^^^^^^^^^^
  File "/usr/local/lib/python3.12/site-packages/django/contrib/auth/__init__.py", line 95, in _get_user_session_key
    return get_user_model()._meta.pk.to_python(request.session[SESSION_KEY])
                                               ~~~~~~~~~~~~~~~^^^^^^^^^^^^^
  File "/usr/local/lib/python3.12/site-packages/django/contrib/sessions/backends/base.py", line 55, in __getitem__
    return self._session[key]
           ^^^^^^^^^^^^^
  File "/usr/local/lib/python3.12/site-packages/django/contrib/sessions/backends/base.py", line 249, in _get_session
    self._session_cache = self.load()
                          ^^^^^^^^^^^
  File "/usr/local/lib/python3.12/site-packages/django/contrib/sessions/backends/db.py", line 55, in load
    s = self._get_session_from_db()
        ^^^^^^^^^^^^^^^^^^^^^^^^^^^
  File "/usr/local/lib/python3.12/site-packages/django/contrib/sessions/backends/db.py", line 34, in _get_session_from_db
    return self.model.objects.get(
           ^^^^^^^^^^^^^^^^^^^^^^^
  File "/usr/local/lib/python3.12/site-packages/django/db/models/manager.py", line 87, in manager_method
    return getattr(self.get_queryset(), name)(*args, **kwargs)
           ^^^^^^^^^^^^^^^^^^^^^^^^^^^^^^^^^^^^^^^^^^^^^^^^^^^
  File "/usr/local/lib/python3.12/site-packages/django/db/models/query.py", line 629, in get
    num = len(clone)
          ^^^^^^^^^^
  File "/usr/local/lib/python3.12/site-packages/django/db/models/query.py", line 366, in __len__
    self._fetch_all()
  File "/usr/local/lib/python3.12/site-packages/django/db/models/query.py", line 1935, in _fetch_all
    self._result_cache = list(self._iterable_class(self))
                         ^^^^^^^^^^^^^^^^^^^^^^^^^^^^^^^^
  File "/usr/local/lib/python3.12/site-packages/django/db/models/query.py", line 91, in __iter__
    results = compiler.execute_sql(
              ^^^^^^^^^^^^^^^^^^^^^
  File "/usr/local/lib/python3.12/site-packages/django/db/models/sql/compiler.py", line 1622, in execute_sql
    cursor.execute(sql, params)
  File "/usr/local/lib/python3.12/site-packages/django/db/backends/utils.py", line 122, in execute
    return super().execute(sql, params)
           ^^^^^^^^^^^^^^^^^^^^^^^^^^^^
  File "/usr/local/lib/python3.12/site-packages/django/db/backends/utils.py", line 79, in execute
    return self._execute_with_wrappers(
           ^^^^^^^^^^^^^^^^^^^^^^^^^^^^
  File "/usr/local/lib/python3.12/site-packages/django/db/backends/utils.py", line 92, in _execute_with_wrappers
    return executor(sql, params, many, context)
           ^^^^^^^^^^^^^^^^^^^^^^^^^^^^^^^^^^^^
  File "/usr/local/lib/python3.12/site-packages/django/db/backends/utils.py", line 100, in _execute
    with self.db.wrap_database_errors:
         ^^^^^^^^^^^^^^^^^^^^^^^^^^^^
  File "/usr/local/lib/python3.12/site-packages/django/db/utils.py", line 91, in __exit__
    raise dj_exc_value.with_traceback(traceback) from exc_value
  File "/usr/local/lib/python3.12/site-packages/django/db/backends/utils.py", line 105, in _execute
    return self.cursor.execute(sql, params)
           ^^^^^^^^^^^^^^^^^^^^^^^^^^^^^^^^
django.db.utils.ProgrammingError: relation "django_session" does not exist
LINE 1: ...ession_data", "django_session"."expire_date" FROM "django_se...
                                                             ^

ERROR 2025-08-02 10:57:52,084 log Internal Server Error: /swagger/
Traceback (most recent call last):
  File "/usr/local/lib/python3.12/site-packages/django/contrib/sessions/backends/base.py", line 244, in _get_session
    return self._session_cache
           ^^^^^^^^^^^^^^^^^^^
AttributeError: 'SessionStore' object has no attribute '_session_cache'

During handling of the above exception, another exception occurred:

Traceback (most recent call last):
  File "/usr/local/lib/python3.12/site-packages/django/db/backends/utils.py", line 105, in _execute
    return self.cursor.execute(sql, params)
           ^^^^^^^^^^^^^^^^^^^^^^^^^^^^^^^^
psycopg2.errors.UndefinedTable: relation "django_session" does not exist
LINE 1: ...ession_data", "django_session"."expire_date" FROM "django_se...
                                                             ^


The above exception was the direct cause of the following exception:

Traceback (most recent call last):
  File "/usr/local/lib/python3.12/site-packages/asgiref/sync.py", line 489, in thread_handler
    raise exc_info[1]
  File "/usr/local/lib/python3.12/site-packages/django/core/handlers/exception.py", line 42, in inner
    response = await get_response(request)
               ^^^^^^^^^^^^^^^^^^^^^^^^^^^
  File "/usr/local/lib/python3.12/site-packages/asgiref/sync.py", line 489, in thread_handler
    raise exc_info[1]
  File "/usr/local/lib/python3.12/site-packages/django/core/handlers/base.py", line 253, in _get_response_async
    response = await wrapped_callback(
               ^^^^^^^^^^^^^^^^^^^^^^^
  File "/usr/local/lib/python3.12/site-packages/asgiref/sync.py", line 439, in __call__
    ret = await asyncio.shield(exec_coro)
          ^^^^^^^^^^^^^^^^^^^^^^^^^^^^^^^
  File "/usr/local/lib/python3.12/concurrent/futures/thread.py", line 59, in run
    result = self.fn(*self.args, **self.kwargs)
             ^^^^^^^^^^^^^^^^^^^^^^^^^^^^^^^^^^
  File "/usr/local/lib/python3.12/site-packages/asgiref/sync.py", line 493, in thread_handler
    return func(*args, **kwargs)
           ^^^^^^^^^^^^^^^^^^^^^
  File "/usr/local/lib/python3.12/site-packages/django/views/decorators/csrf.py", line 65, in _view_wrapper
    return view_func(request, *args, **kwargs)
           ^^^^^^^^^^^^^^^^^^^^^^^^^^^^^^^^^^^
  File "/usr/local/lib/python3.12/site-packages/django/views/generic/base.py", line 104, in view
    return self.dispatch(request, *args, **kwargs)
           ^^^^^^^^^^^^^^^^^^^^^^^^^^^^^^^^^^^^^^^
  File "/usr/local/lib/python3.12/site-packages/rest_framework/views.py", line 515, in dispatch
    response = self.handle_exception(exc)
               ^^^^^^^^^^^^^^^^^^^^^^^^^^
  File "/usr/local/lib/python3.12/site-packages/rest_framework/views.py", line 475, in handle_exception
    self.raise_uncaught_exception(exc)
  File "/usr/local/lib/python3.12/site-packages/rest_framework/views.py", line 486, in raise_uncaught_exception
    raise exc
  File "/usr/local/lib/python3.12/site-packages/rest_framework/views.py", line 503, in dispatch
    self.initial(request, *args, **kwargs)
  File "/usr/local/lib/python3.12/site-packages/rest_framework/views.py", line 420, in initial
    self.perform_authentication(request)
  File "/usr/local/lib/python3.12/site-packages/rest_framework/views.py", line 330, in perform_authentication
    request.user
  File "/usr/local/lib/python3.12/site-packages/rest_framework/request.py", line 232, in user
    self._authenticate()
  File "/usr/local/lib/python3.12/site-packages/rest_framework/request.py", line 385, in _authenticate
    user_auth_tuple = authenticator.authenticate(self)
                      ^^^^^^^^^^^^^^^^^^^^^^^^^^^^^^^^
  File "/usr/local/lib/python3.12/site-packages/rest_framework/authentication.py", line 127, in authenticate
    if not user or not user.is_active:
           ^^^^
  File "/usr/local/lib/python3.12/site-packages/django/utils/functional.py", line 251, in inner
    self._setup()
  File "/usr/local/lib/python3.12/site-packages/django/utils/functional.py", line 404, in _setup
    self._wrapped = self._setupfunc()
                    ^^^^^^^^^^^^^^^^^
  File "/usr/local/lib/python3.12/site-packages/django/contrib/auth/middleware.py", line 39, in <lambda>
    request.user = SimpleLazyObject(lambda: get_user(request))
                                            ^^^^^^^^^^^^^^^^^
  File "/usr/local/lib/python3.12/site-packages/django/contrib/auth/middleware.py", line 19, in get_user
    request._cached_user = auth.get_user(request)
                           ^^^^^^^^^^^^^^^^^^^^^^
  File "/usr/local/lib/python3.12/site-packages/django/contrib/auth/__init__.py", line 304, in get_user
    user_id = _get_user_session_key(request)
              ^^^^^^^^^^^^^^^^^^^^^^^^^^^^^^
  File "/usr/local/lib/python3.12/site-packages/django/contrib/auth/__init__.py", line 95, in _get_user_session_key
    return get_user_model()._meta.pk.to_python(request.session[SESSION_KEY])
                                               ~~~~~~~~~~~~~~~^^^^^^^^^^^^^
  File "/usr/local/lib/python3.12/site-packages/django/contrib/sessions/backends/base.py", line 55, in __getitem__
    return self._session[key]
           ^^^^^^^^^^^^^
  File "/usr/local/lib/python3.12/site-packages/django/contrib/sessions/backends/base.py", line 249, in _get_session
    self._session_cache = self.load()
                          ^^^^^^^^^^^
  File "/usr/local/lib/python3.12/site-packages/django/contrib/sessions/backends/db.py", line 55, in load
    s = self._get_session_from_db()
        ^^^^^^^^^^^^^^^^^^^^^^^^^^^
  File "/usr/local/lib/python3.12/site-packages/django/contrib/sessions/backends/db.py", line 34, in _get_session_from_db
    return self.model.objects.get(
           ^^^^^^^^^^^^^^^^^^^^^^^
  File "/usr/local/lib/python3.12/site-packages/django/db/models/manager.py", line 87, in manager_method
    return getattr(self.get_queryset(), name)(*args, **kwargs)
           ^^^^^^^^^^^^^^^^^^^^^^^^^^^^^^^^^^^^^^^^^^^^^^^^^^^
  File "/usr/local/lib/python3.12/site-packages/django/db/models/query.py", line 629, in get
    num = len(clone)
          ^^^^^^^^^^
  File "/usr/local/lib/python3.12/site-packages/django/db/models/query.py", line 366, in __len__
    self._fetch_all()
  File "/usr/local/lib/python3.12/site-packages/django/db/models/query.py", line 1935, in _fetch_all
    self._result_cache = list(self._iterable_class(self))
                         ^^^^^^^^^^^^^^^^^^^^^^^^^^^^^^^^
  File "/usr/local/lib/python3.12/site-packages/django/db/models/query.py", line 91, in __iter__
    results = compiler.execute_sql(
              ^^^^^^^^^^^^^^^^^^^^^
  File "/usr/local/lib/python3.12/site-packages/django/db/models/sql/compiler.py", line 1622, in execute_sql
    cursor.execute(sql, params)
  File "/usr/local/lib/python3.12/site-packages/django/db/backends/utils.py", line 122, in execute
    return super().execute(sql, params)
           ^^^^^^^^^^^^^^^^^^^^^^^^^^^^
  File "/usr/local/lib/python3.12/site-packages/django/db/backends/utils.py", line 79, in execute
    return self._execute_with_wrappers(
           ^^^^^^^^^^^^^^^^^^^^^^^^^^^^
  File "/usr/local/lib/python3.12/site-packages/django/db/backends/utils.py", line 92, in _execute_with_wrappers
    return executor(sql, params, many, context)
           ^^^^^^^^^^^^^^^^^^^^^^^^^^^^^^^^^^^^
  File "/usr/local/lib/python3.12/site-packages/django/db/backends/utils.py", line 100, in _execute
    with self.db.wrap_database_errors:
         ^^^^^^^^^^^^^^^^^^^^^^^^^^^^
  File "/usr/local/lib/python3.12/site-packages/django/db/utils.py", line 91, in __exit__
    raise dj_exc_value.with_traceback(traceback) from exc_value
  File "/usr/local/lib/python3.12/site-packages/django/db/backends/utils.py", line 105, in _execute
    return self.cursor.execute(sql, params)
           ^^^^^^^^^^^^^^^^^^^^^^^^^^^^^^^^
django.db.utils.ProgrammingError: relation "django_session" does not exist
LINE 1: ...ession_data", "django_session"."expire_date" FROM "django_se...
                                                             ^

ERROR 2025-08-02 10:58:22,607 log Internal Server Error: /swagger/
Traceback (most recent call last):
  File "/usr/local/lib/python3.12/site-packages/django/contrib/sessions/backends/base.py", line 244, in _get_session
    return self._session_cache
           ^^^^^^^^^^^^^^^^^^^
AttributeError: 'SessionStore' object has no attribute '_session_cache'

During handling of the above exception, another exception occurred:

Traceback (most recent call last):
  File "/usr/local/lib/python3.12/site-packages/django/db/backends/utils.py", line 105, in _execute
    return self.cursor.execute(sql, params)
           ^^^^^^^^^^^^^^^^^^^^^^^^^^^^^^^^
psycopg2.errors.UndefinedTable: relation "django_session" does not exist
LINE 1: ...ession_data", "django_session"."expire_date" FROM "django_se...
                                                             ^


The above exception was the direct cause of the following exception:

Traceback (most recent call last):
  File "/usr/local/lib/python3.12/site-packages/asgiref/sync.py", line 489, in thread_handler
    raise exc_info[1]
  File "/usr/local/lib/python3.12/site-packages/django/core/handlers/exception.py", line 42, in inner
    response = await get_response(request)
               ^^^^^^^^^^^^^^^^^^^^^^^^^^^
  File "/usr/local/lib/python3.12/site-packages/asgiref/sync.py", line 489, in thread_handler
    raise exc_info[1]
  File "/usr/local/lib/python3.12/site-packages/django/core/handlers/base.py", line 253, in _get_response_async
    response = await wrapped_callback(
               ^^^^^^^^^^^^^^^^^^^^^^^
  File "/usr/local/lib/python3.12/site-packages/asgiref/sync.py", line 439, in __call__
    ret = await asyncio.shield(exec_coro)
          ^^^^^^^^^^^^^^^^^^^^^^^^^^^^^^^
  File "/usr/local/lib/python3.12/concurrent/futures/thread.py", line 59, in run
    result = self.fn(*self.args, **self.kwargs)
             ^^^^^^^^^^^^^^^^^^^^^^^^^^^^^^^^^^
  File "/usr/local/lib/python3.12/site-packages/asgiref/sync.py", line 493, in thread_handler
    return func(*args, **kwargs)
           ^^^^^^^^^^^^^^^^^^^^^
  File "/usr/local/lib/python3.12/site-packages/django/views/decorators/csrf.py", line 65, in _view_wrapper
    return view_func(request, *args, **kwargs)
           ^^^^^^^^^^^^^^^^^^^^^^^^^^^^^^^^^^^
  File "/usr/local/lib/python3.12/site-packages/django/views/generic/base.py", line 104, in view
    return self.dispatch(request, *args, **kwargs)
           ^^^^^^^^^^^^^^^^^^^^^^^^^^^^^^^^^^^^^^^
  File "/usr/local/lib/python3.12/site-packages/rest_framework/views.py", line 515, in dispatch
    response = self.handle_exception(exc)
               ^^^^^^^^^^^^^^^^^^^^^^^^^^
  File "/usr/local/lib/python3.12/site-packages/rest_framework/views.py", line 475, in handle_exception
    self.raise_uncaught_exception(exc)
  File "/usr/local/lib/python3.12/site-packages/rest_framework/views.py", line 486, in raise_uncaught_exception
    raise exc
  File "/usr/local/lib/python3.12/site-packages/rest_framework/views.py", line 503, in dispatch
    self.initial(request, *args, **kwargs)
  File "/usr/local/lib/python3.12/site-packages/rest_framework/views.py", line 420, in initial
    self.perform_authentication(request)
  File "/usr/local/lib/python3.12/site-packages/rest_framework/views.py", line 330, in perform_authentication
    request.user
  File "/usr/local/lib/python3.12/site-packages/rest_framework/request.py", line 232, in user
    self._authenticate()
  File "/usr/local/lib/python3.12/site-packages/rest_framework/request.py", line 385, in _authenticate
    user_auth_tuple = authenticator.authenticate(self)
                      ^^^^^^^^^^^^^^^^^^^^^^^^^^^^^^^^
  File "/usr/local/lib/python3.12/site-packages/rest_framework/authentication.py", line 127, in authenticate
    if not user or not user.is_active:
           ^^^^
  File "/usr/local/lib/python3.12/site-packages/django/utils/functional.py", line 251, in inner
    self._setup()
  File "/usr/local/lib/python3.12/site-packages/django/utils/functional.py", line 404, in _setup
    self._wrapped = self._setupfunc()
                    ^^^^^^^^^^^^^^^^^
  File "/usr/local/lib/python3.12/site-packages/django/contrib/auth/middleware.py", line 39, in <lambda>
    request.user = SimpleLazyObject(lambda: get_user(request))
                                            ^^^^^^^^^^^^^^^^^
  File "/usr/local/lib/python3.12/site-packages/django/contrib/auth/middleware.py", line 19, in get_user
    request._cached_user = auth.get_user(request)
                           ^^^^^^^^^^^^^^^^^^^^^^
  File "/usr/local/lib/python3.12/site-packages/django/contrib/auth/__init__.py", line 304, in get_user
    user_id = _get_user_session_key(request)
              ^^^^^^^^^^^^^^^^^^^^^^^^^^^^^^
  File "/usr/local/lib/python3.12/site-packages/django/contrib/auth/__init__.py", line 95, in _get_user_session_key
    return get_user_model()._meta.pk.to_python(request.session[SESSION_KEY])
                                               ~~~~~~~~~~~~~~~^^^^^^^^^^^^^
  File "/usr/local/lib/python3.12/site-packages/django/contrib/sessions/backends/base.py", line 55, in __getitem__
    return self._session[key]
           ^^^^^^^^^^^^^
  File "/usr/local/lib/python3.12/site-packages/django/contrib/sessions/backends/base.py", line 249, in _get_session
    self._session_cache = self.load()
                          ^^^^^^^^^^^
  File "/usr/local/lib/python3.12/site-packages/django/contrib/sessions/backends/db.py", line 55, in load
    s = self._get_session_from_db()
        ^^^^^^^^^^^^^^^^^^^^^^^^^^^
  File "/usr/local/lib/python3.12/site-packages/django/contrib/sessions/backends/db.py", line 34, in _get_session_from_db
    return self.model.objects.get(
           ^^^^^^^^^^^^^^^^^^^^^^^
  File "/usr/local/lib/python3.12/site-packages/django/db/models/manager.py", line 87, in manager_method
    return getattr(self.get_queryset(), name)(*args, **kwargs)
           ^^^^^^^^^^^^^^^^^^^^^^^^^^^^^^^^^^^^^^^^^^^^^^^^^^^
  File "/usr/local/lib/python3.12/site-packages/django/db/models/query.py", line 629, in get
    num = len(clone)
          ^^^^^^^^^^
  File "/usr/local/lib/python3.12/site-packages/django/db/models/query.py", line 366, in __len__
    self._fetch_all()
  File "/usr/local/lib/python3.12/site-packages/django/db/models/query.py", line 1935, in _fetch_all
    self._result_cache = list(self._iterable_class(self))
                         ^^^^^^^^^^^^^^^^^^^^^^^^^^^^^^^^
  File "/usr/local/lib/python3.12/site-packages/django/db/models/query.py", line 91, in __iter__
    results = compiler.execute_sql(
              ^^^^^^^^^^^^^^^^^^^^^
  File "/usr/local/lib/python3.12/site-packages/django/db/models/sql/compiler.py", line 1622, in execute_sql
    cursor.execute(sql, params)
  File "/usr/local/lib/python3.12/site-packages/django/db/backends/utils.py", line 122, in execute
    return super().execute(sql, params)
           ^^^^^^^^^^^^^^^^^^^^^^^^^^^^
  File "/usr/local/lib/python3.12/site-packages/django/db/backends/utils.py", line 79, in execute
    return self._execute_with_wrappers(
           ^^^^^^^^^^^^^^^^^^^^^^^^^^^^
  File "/usr/local/lib/python3.12/site-packages/django/db/backends/utils.py", line 92, in _execute_with_wrappers
    return executor(sql, params, many, context)
           ^^^^^^^^^^^^^^^^^^^^^^^^^^^^^^^^^^^^
  File "/usr/local/lib/python3.12/site-packages/django/db/backends/utils.py", line 100, in _execute
    with self.db.wrap_database_errors:
         ^^^^^^^^^^^^^^^^^^^^^^^^^^^^
  File "/usr/local/lib/python3.12/site-packages/django/db/utils.py", line 91, in __exit__
    raise dj_exc_value.with_traceback(traceback) from exc_value
  File "/usr/local/lib/python3.12/site-packages/django/db/backends/utils.py", line 105, in _execute
    return self.cursor.execute(sql, params)
           ^^^^^^^^^^^^^^^^^^^^^^^^^^^^^^^^
django.db.utils.ProgrammingError: relation "django_session" does not exist
LINE 1: ...ession_data", "django_session"."expire_date" FROM "django_se...
                                                             ^

ERROR 2025-08-02 10:58:23,090 log Internal Server Error: /swagger/
Traceback (most recent call last):
  File "/usr/local/lib/python3.12/site-packages/django/contrib/sessions/backends/base.py", line 244, in _get_session
    return self._session_cache
           ^^^^^^^^^^^^^^^^^^^
AttributeError: 'SessionStore' object has no attribute '_session_cache'

During handling of the above exception, another exception occurred:

Traceback (most recent call last):
  File "/usr/local/lib/python3.12/site-packages/django/db/backends/utils.py", line 105, in _execute
    return self.cursor.execute(sql, params)
           ^^^^^^^^^^^^^^^^^^^^^^^^^^^^^^^^
psycopg2.errors.UndefinedTable: relation "django_session" does not exist
LINE 1: ...ession_data", "django_session"."expire_date" FROM "django_se...
                                                             ^


The above exception was the direct cause of the following exception:

Traceback (most recent call last):
  File "/usr/local/lib/python3.12/site-packages/asgiref/sync.py", line 489, in thread_handler
    raise exc_info[1]
  File "/usr/local/lib/python3.12/site-packages/django/core/handlers/exception.py", line 42, in inner
    response = await get_response(request)
               ^^^^^^^^^^^^^^^^^^^^^^^^^^^
  File "/usr/local/lib/python3.12/site-packages/asgiref/sync.py", line 489, in thread_handler
    raise exc_info[1]
  File "/usr/local/lib/python3.12/site-packages/django/core/handlers/base.py", line 253, in _get_response_async
    response = await wrapped_callback(
               ^^^^^^^^^^^^^^^^^^^^^^^
  File "/usr/local/lib/python3.12/site-packages/asgiref/sync.py", line 439, in __call__
    ret = await asyncio.shield(exec_coro)
          ^^^^^^^^^^^^^^^^^^^^^^^^^^^^^^^
  File "/usr/local/lib/python3.12/concurrent/futures/thread.py", line 59, in run
    result = self.fn(*self.args, **self.kwargs)
             ^^^^^^^^^^^^^^^^^^^^^^^^^^^^^^^^^^
  File "/usr/local/lib/python3.12/site-packages/asgiref/sync.py", line 493, in thread_handler
    return func(*args, **kwargs)
           ^^^^^^^^^^^^^^^^^^^^^
  File "/usr/local/lib/python3.12/site-packages/django/views/decorators/csrf.py", line 65, in _view_wrapper
    return view_func(request, *args, **kwargs)
           ^^^^^^^^^^^^^^^^^^^^^^^^^^^^^^^^^^^
  File "/usr/local/lib/python3.12/site-packages/django/views/generic/base.py", line 104, in view
    return self.dispatch(request, *args, **kwargs)
           ^^^^^^^^^^^^^^^^^^^^^^^^^^^^^^^^^^^^^^^
  File "/usr/local/lib/python3.12/site-packages/rest_framework/views.py", line 515, in dispatch
    response = self.handle_exception(exc)
               ^^^^^^^^^^^^^^^^^^^^^^^^^^
  File "/usr/local/lib/python3.12/site-packages/rest_framework/views.py", line 475, in handle_exception
    self.raise_uncaught_exception(exc)
  File "/usr/local/lib/python3.12/site-packages/rest_framework/views.py", line 486, in raise_uncaught_exception
    raise exc
  File "/usr/local/lib/python3.12/site-packages/rest_framework/views.py", line 503, in dispatch
    self.initial(request, *args, **kwargs)
  File "/usr/local/lib/python3.12/site-packages/rest_framework/views.py", line 420, in initial
    self.perform_authentication(request)
  File "/usr/local/lib/python3.12/site-packages/rest_framework/views.py", line 330, in perform_authentication
    request.user
  File "/usr/local/lib/python3.12/site-packages/rest_framework/request.py", line 232, in user
    self._authenticate()
  File "/usr/local/lib/python3.12/site-packages/rest_framework/request.py", line 385, in _authenticate
    user_auth_tuple = authenticator.authenticate(self)
                      ^^^^^^^^^^^^^^^^^^^^^^^^^^^^^^^^
  File "/usr/local/lib/python3.12/site-packages/rest_framework/authentication.py", line 127, in authenticate
    if not user or not user.is_active:
           ^^^^
  File "/usr/local/lib/python3.12/site-packages/django/utils/functional.py", line 251, in inner
    self._setup()
  File "/usr/local/lib/python3.12/site-packages/django/utils/functional.py", line 404, in _setup
    self._wrapped = self._setupfunc()
                    ^^^^^^^^^^^^^^^^^
  File "/usr/local/lib/python3.12/site-packages/django/contrib/auth/middleware.py", line 39, in <lambda>
    request.user = SimpleLazyObject(lambda: get_user(request))
                                            ^^^^^^^^^^^^^^^^^
  File "/usr/local/lib/python3.12/site-packages/django/contrib/auth/middleware.py", line 19, in get_user
    request._cached_user = auth.get_user(request)
                           ^^^^^^^^^^^^^^^^^^^^^^
  File "/usr/local/lib/python3.12/site-packages/django/contrib/auth/__init__.py", line 304, in get_user
    user_id = _get_user_session_key(request)
              ^^^^^^^^^^^^^^^^^^^^^^^^^^^^^^
  File "/usr/local/lib/python3.12/site-packages/django/contrib/auth/__init__.py", line 95, in _get_user_session_key
    return get_user_model()._meta.pk.to_python(request.session[SESSION_KEY])
                                               ~~~~~~~~~~~~~~~^^^^^^^^^^^^^
  File "/usr/local/lib/python3.12/site-packages/django/contrib/sessions/backends/base.py", line 55, in __getitem__
    return self._session[key]
           ^^^^^^^^^^^^^
  File "/usr/local/lib/python3.12/site-packages/django/contrib/sessions/backends/base.py", line 249, in _get_session
    self._session_cache = self.load()
                          ^^^^^^^^^^^
  File "/usr/local/lib/python3.12/site-packages/django/contrib/sessions/backends/db.py", line 55, in load
    s = self._get_session_from_db()
        ^^^^^^^^^^^^^^^^^^^^^^^^^^^
  File "/usr/local/lib/python3.12/site-packages/django/contrib/sessions/backends/db.py", line 34, in _get_session_from_db
    return self.model.objects.get(
           ^^^^^^^^^^^^^^^^^^^^^^^
  File "/usr/local/lib/python3.12/site-packages/django/db/models/manager.py", line 87, in manager_method
    return getattr(self.get_queryset(), name)(*args, **kwargs)
           ^^^^^^^^^^^^^^^^^^^^^^^^^^^^^^^^^^^^^^^^^^^^^^^^^^^
  File "/usr/local/lib/python3.12/site-packages/django/db/models/query.py", line 629, in get
    num = len(clone)
          ^^^^^^^^^^
  File "/usr/local/lib/python3.12/site-packages/django/db/models/query.py", line 366, in __len__
    self._fetch_all()
  File "/usr/local/lib/python3.12/site-packages/django/db/models/query.py", line 1935, in _fetch_all
    self._result_cache = list(self._iterable_class(self))
                         ^^^^^^^^^^^^^^^^^^^^^^^^^^^^^^^^
  File "/usr/local/lib/python3.12/site-packages/django/db/models/query.py", line 91, in __iter__
    results = compiler.execute_sql(
              ^^^^^^^^^^^^^^^^^^^^^
  File "/usr/local/lib/python3.12/site-packages/django/db/models/sql/compiler.py", line 1622, in execute_sql
    cursor.execute(sql, params)
  File "/usr/local/lib/python3.12/site-packages/django/db/backends/utils.py", line 122, in execute
    return super().execute(sql, params)
           ^^^^^^^^^^^^^^^^^^^^^^^^^^^^
  File "/usr/local/lib/python3.12/site-packages/django/db/backends/utils.py", line 79, in execute
    return self._execute_with_wrappers(
           ^^^^^^^^^^^^^^^^^^^^^^^^^^^^
  File "/usr/local/lib/python3.12/site-packages/django/db/backends/utils.py", line 92, in _execute_with_wrappers
    return executor(sql, params, many, context)
           ^^^^^^^^^^^^^^^^^^^^^^^^^^^^^^^^^^^^
  File "/usr/local/lib/python3.12/site-packages/django/db/backends/utils.py", line 100, in _execute
    with self.db.wrap_database_errors:
         ^^^^^^^^^^^^^^^^^^^^^^^^^^^^
  File "/usr/local/lib/python3.12/site-packages/django/db/utils.py", line 91, in __exit__
    raise dj_exc_value.with_traceback(traceback) from exc_value
  File "/usr/local/lib/python3.12/site-packages/django/db/backends/utils.py", line 105, in _execute
    return self.cursor.execute(sql, params)
           ^^^^^^^^^^^^^^^^^^^^^^^^^^^^^^^^
django.db.utils.ProgrammingError: relation "django_session" does not exist
LINE 1: ...ession_data", "django_session"."expire_date" FROM "django_se...
                                                             ^

ERROR 2025-08-02 10:58:23,294 log Internal Server Error: /swagger/
Traceback (most recent call last):
  File "/usr/local/lib/python3.12/site-packages/django/contrib/sessions/backends/base.py", line 244, in _get_session
    return self._session_cache
           ^^^^^^^^^^^^^^^^^^^
AttributeError: 'SessionStore' object has no attribute '_session_cache'

During handling of the above exception, another exception occurred:

Traceback (most recent call last):
  File "/usr/local/lib/python3.12/site-packages/django/db/backends/utils.py", line 105, in _execute
    return self.cursor.execute(sql, params)
           ^^^^^^^^^^^^^^^^^^^^^^^^^^^^^^^^
psycopg2.errors.UndefinedTable: relation "django_session" does not exist
LINE 1: ...ession_data", "django_session"."expire_date" FROM "django_se...
                                                             ^


The above exception was the direct cause of the following exception:

Traceback (most recent call last):
  File "/usr/local/lib/python3.12/site-packages/asgiref/sync.py", line 489, in thread_handler
    raise exc_info[1]
  File "/usr/local/lib/python3.12/site-packages/django/core/handlers/exception.py", line 42, in inner
    response = await get_response(request)
               ^^^^^^^^^^^^^^^^^^^^^^^^^^^
  File "/usr/local/lib/python3.12/site-packages/asgiref/sync.py", line 489, in thread_handler
    raise exc_info[1]
  File "/usr/local/lib/python3.12/site-packages/django/core/handlers/base.py", line 253, in _get_response_async
    response = await wrapped_callback(
               ^^^^^^^^^^^^^^^^^^^^^^^
  File "/usr/local/lib/python3.12/site-packages/asgiref/sync.py", line 439, in __call__
    ret = await asyncio.shield(exec_coro)
          ^^^^^^^^^^^^^^^^^^^^^^^^^^^^^^^
  File "/usr/local/lib/python3.12/concurrent/futures/thread.py", line 59, in run
    result = self.fn(*self.args, **self.kwargs)
             ^^^^^^^^^^^^^^^^^^^^^^^^^^^^^^^^^^
  File "/usr/local/lib/python3.12/site-packages/asgiref/sync.py", line 493, in thread_handler
    return func(*args, **kwargs)
           ^^^^^^^^^^^^^^^^^^^^^
  File "/usr/local/lib/python3.12/site-packages/django/views/decorators/csrf.py", line 65, in _view_wrapper
    return view_func(request, *args, **kwargs)
           ^^^^^^^^^^^^^^^^^^^^^^^^^^^^^^^^^^^
  File "/usr/local/lib/python3.12/site-packages/django/views/generic/base.py", line 104, in view
    return self.dispatch(request, *args, **kwargs)
           ^^^^^^^^^^^^^^^^^^^^^^^^^^^^^^^^^^^^^^^
  File "/usr/local/lib/python3.12/site-packages/rest_framework/views.py", line 515, in dispatch
    response = self.handle_exception(exc)
               ^^^^^^^^^^^^^^^^^^^^^^^^^^
  File "/usr/local/lib/python3.12/site-packages/rest_framework/views.py", line 475, in handle_exception
    self.raise_uncaught_exception(exc)
  File "/usr/local/lib/python3.12/site-packages/rest_framework/views.py", line 486, in raise_uncaught_exception
    raise exc
  File "/usr/local/lib/python3.12/site-packages/rest_framework/views.py", line 503, in dispatch
    self.initial(request, *args, **kwargs)
  File "/usr/local/lib/python3.12/site-packages/rest_framework/views.py", line 420, in initial
    self.perform_authentication(request)
  File "/usr/local/lib/python3.12/site-packages/rest_framework/views.py", line 330, in perform_authentication
    request.user
  File "/usr/local/lib/python3.12/site-packages/rest_framework/request.py", line 232, in user
    self._authenticate()
  File "/usr/local/lib/python3.12/site-packages/rest_framework/request.py", line 385, in _authenticate
    user_auth_tuple = authenticator.authenticate(self)
                      ^^^^^^^^^^^^^^^^^^^^^^^^^^^^^^^^
  File "/usr/local/lib/python3.12/site-packages/rest_framework/authentication.py", line 127, in authenticate
    if not user or not user.is_active:
           ^^^^
  File "/usr/local/lib/python3.12/site-packages/django/utils/functional.py", line 251, in inner
    self._setup()
  File "/usr/local/lib/python3.12/site-packages/django/utils/functional.py", line 404, in _setup
    self._wrapped = self._setupfunc()
                    ^^^^^^^^^^^^^^^^^
  File "/usr/local/lib/python3.12/site-packages/django/contrib/auth/middleware.py", line 39, in <lambda>
    request.user = SimpleLazyObject(lambda: get_user(request))
                                            ^^^^^^^^^^^^^^^^^
  File "/usr/local/lib/python3.12/site-packages/django/contrib/auth/middleware.py", line 19, in get_user
    request._cached_user = auth.get_user(request)
                           ^^^^^^^^^^^^^^^^^^^^^^
  File "/usr/local/lib/python3.12/site-packages/django/contrib/auth/__init__.py", line 304, in get_user
    user_id = _get_user_session_key(request)
              ^^^^^^^^^^^^^^^^^^^^^^^^^^^^^^
  File "/usr/local/lib/python3.12/site-packages/django/contrib/auth/__init__.py", line 95, in _get_user_session_key
    return get_user_model()._meta.pk.to_python(request.session[SESSION_KEY])
                                               ~~~~~~~~~~~~~~~^^^^^^^^^^^^^
  File "/usr/local/lib/python3.12/site-packages/django/contrib/sessions/backends/base.py", line 55, in __getitem__
    return self._session[key]
           ^^^^^^^^^^^^^
  File "/usr/local/lib/python3.12/site-packages/django/contrib/sessions/backends/base.py", line 249, in _get_session
    self._session_cache = self.load()
                          ^^^^^^^^^^^
  File "/usr/local/lib/python3.12/site-packages/django/contrib/sessions/backends/db.py", line 55, in load
    s = self._get_session_from_db()
        ^^^^^^^^^^^^^^^^^^^^^^^^^^^
  File "/usr/local/lib/python3.12/site-packages/django/contrib/sessions/backends/db.py", line 34, in _get_session_from_db
    return self.model.objects.get(
           ^^^^^^^^^^^^^^^^^^^^^^^
  File "/usr/local/lib/python3.12/site-packages/django/db/models/manager.py", line 87, in manager_method
    return getattr(self.get_queryset(), name)(*args, **kwargs)
           ^^^^^^^^^^^^^^^^^^^^^^^^^^^^^^^^^^^^^^^^^^^^^^^^^^^
  File "/usr/local/lib/python3.12/site-packages/django/db/models/query.py", line 629, in get
    num = len(clone)
          ^^^^^^^^^^
  File "/usr/local/lib/python3.12/site-packages/django/db/models/query.py", line 366, in __len__
    self._fetch_all()
  File "/usr/local/lib/python3.12/site-packages/django/db/models/query.py", line 1935, in _fetch_all
    self._result_cache = list(self._iterable_class(self))
                         ^^^^^^^^^^^^^^^^^^^^^^^^^^^^^^^^
  File "/usr/local/lib/python3.12/site-packages/django/db/models/query.py", line 91, in __iter__
    results = compiler.execute_sql(
              ^^^^^^^^^^^^^^^^^^^^^
  File "/usr/local/lib/python3.12/site-packages/django/db/models/sql/compiler.py", line 1622, in execute_sql
    cursor.execute(sql, params)
  File "/usr/local/lib/python3.12/site-packages/django/db/backends/utils.py", line 122, in execute
    return super().execute(sql, params)
           ^^^^^^^^^^^^^^^^^^^^^^^^^^^^
  File "/usr/local/lib/python3.12/site-packages/django/db/backends/utils.py", line 79, in execute
    return self._execute_with_wrappers(
           ^^^^^^^^^^^^^^^^^^^^^^^^^^^^
  File "/usr/local/lib/python3.12/site-packages/django/db/backends/utils.py", line 92, in _execute_with_wrappers
    return executor(sql, params, many, context)
           ^^^^^^^^^^^^^^^^^^^^^^^^^^^^^^^^^^^^
  File "/usr/local/lib/python3.12/site-packages/django/db/backends/utils.py", line 100, in _execute
    with self.db.wrap_database_errors:
         ^^^^^^^^^^^^^^^^^^^^^^^^^^^^
  File "/usr/local/lib/python3.12/site-packages/django/db/utils.py", line 91, in __exit__
    raise dj_exc_value.with_traceback(traceback) from exc_value
  File "/usr/local/lib/python3.12/site-packages/django/db/backends/utils.py", line 105, in _execute
    return self.cursor.execute(sql, params)
           ^^^^^^^^^^^^^^^^^^^^^^^^^^^^^^^^
django.db.utils.ProgrammingError: relation "django_session" does not exist
LINE 1: ...ession_data", "django_session"."expire_date" FROM "django_se...
                                                             ^

WARNING 2025-08-02 10:58:47,548 log Forbidden: /swagger/
WARNING 2025-08-02 11:03:03,229 log Forbidden (Origin checking failed - http://localhost:8000 does not match any trusted origins.): /admin/login/
ERROR 2025-08-02 12:14:16,766 log Internal Server Error: /admin/accounts/user/
Traceback (most recent call last):
  File "/usr/local/lib/python3.12/site-packages/asgiref/sync.py", line 489, in thread_handler
    raise exc_info[1]
  File "/usr/local/lib/python3.12/site-packages/django/core/handlers/exception.py", line 42, in inner
    response = await get_response(request)
               ^^^^^^^^^^^^^^^^^^^^^^^^^^^
  File "/usr/local/lib/python3.12/site-packages/asgiref/sync.py", line 489, in thread_handler
    raise exc_info[1]
  File "/usr/local/lib/python3.12/site-packages/django/core/handlers/base.py", line 253, in _get_response_async
    response = await wrapped_callback(
               ^^^^^^^^^^^^^^^^^^^^^^^
  File "/usr/local/lib/python3.12/site-packages/asgiref/sync.py", line 439, in __call__
    ret = await asyncio.shield(exec_coro)
          ^^^^^^^^^^^^^^^^^^^^^^^^^^^^^^^
  File "/usr/local/lib/python3.12/concurrent/futures/thread.py", line 59, in run
    result = self.fn(*self.args, **self.kwargs)
             ^^^^^^^^^^^^^^^^^^^^^^^^^^^^^^^^^^
  File "/usr/local/lib/python3.12/site-packages/asgiref/sync.py", line 493, in thread_handler
    return func(*args, **kwargs)
           ^^^^^^^^^^^^^^^^^^^^^
  File "/usr/local/lib/python3.12/site-packages/django/contrib/admin/options.py", line 719, in wrapper
    return self.admin_site.admin_view(view)(*args, **kwargs)
           ^^^^^^^^^^^^^^^^^^^^^^^^^^^^^^^^^^^^^^^^^^^^^^^^^
  File "/usr/local/lib/python3.12/site-packages/django/utils/decorators.py", line 192, in _view_wrapper
    result = _process_exception(request, e)
             ^^^^^^^^^^^^^^^^^^^^^^^^^^^^^^
  File "/usr/local/lib/python3.12/site-packages/django/utils/decorators.py", line 190, in _view_wrapper
    response = view_func(request, *args, **kwargs)
               ^^^^^^^^^^^^^^^^^^^^^^^^^^^^^^^^^^^
  File "/usr/local/lib/python3.12/site-packages/django/views/decorators/cache.py", line 80, in _view_wrapper
    response = view_func(request, *args, **kwargs)
               ^^^^^^^^^^^^^^^^^^^^^^^^^^^^^^^^^^^
  File "/usr/local/lib/python3.12/site-packages/django/contrib/admin/sites.py", line 246, in inner
    return view(request, *args, **kwargs)
           ^^^^^^^^^^^^^^^^^^^^^^^^^^^^^^
  File "/usr/local/lib/python3.12/site-packages/django/utils/decorators.py", line 48, in _wrapper
    return bound_method(*args, **kwargs)
           ^^^^^^^^^^^^^^^^^^^^^^^^^^^^^
  File "/usr/local/lib/python3.12/site-packages/django/utils/decorators.py", line 192, in _view_wrapper
    result = _process_exception(request, e)
             ^^^^^^^^^^^^^^^^^^^^^^^^^^^^^^
  File "/usr/local/lib/python3.12/site-packages/django/utils/decorators.py", line 190, in _view_wrapper
    response = view_func(request, *args, **kwargs)
               ^^^^^^^^^^^^^^^^^^^^^^^^^^^^^^^^^^^
  File "/usr/local/lib/python3.12/site-packages/django/contrib/admin/options.py", line 2024, in changelist_view
    cl = self.get_changelist_instance(request)
         ^^^^^^^^^^^^^^^^^^^^^^^^^^^^^^^^^^^^^
  File "/usr/local/lib/python3.12/site-packages/django/contrib/admin/options.py", line 867, in get_changelist_instance
    return ChangeList(
           ^^^^^^^^^^^
  File "/usr/local/lib/python3.12/site-packages/django/contrib/admin/views/main.py", line 91, in __init__
    self.root_queryset = model_admin.get_queryset(request)
                         ^^^^^^^^^^^^^^^^^^^^^^^^^^^^^^^^^
  File "/usr/local/lib/python3.12/site-packages/django/contrib/admin/options.py", line 440, in get_queryset
    qs = qs.order_by(*ordering)
         ^^^^^^^^^^^^^^^^^^^^^^
  File "/usr/local/lib/python3.12/site-packages/django/db/models/query.py", line 1708, in order_by
    obj.query.add_ordering(*field_names)
  File "/usr/local/lib/python3.12/site-packages/django/db/models/sql/query.py", line 2288, in add_ordering
    self.names_to_path(item.split(LOOKUP_SEP), self.model._meta)
  File "/usr/local/lib/python3.12/site-packages/django/db/models/sql/query.py", line 1802, in names_to_path
    raise FieldError(
django.core.exceptions.FieldError: Cannot resolve keyword 'username' into field. Choices are: created_at, date_joined, email, first_name, groups, id, is_active, is_staff, is_superuser, last_login, last_name, logentry, password, updated_at, user_permissions
ERROR 2025-08-02 12:14:48,974 log Internal Server Error: /admin/accounts/user/
Traceback (most recent call last):
  File "/usr/local/lib/python3.12/site-packages/asgiref/sync.py", line 489, in thread_handler
    raise exc_info[1]
  File "/usr/local/lib/python3.12/site-packages/django/core/handlers/exception.py", line 42, in inner
    response = await get_response(request)
               ^^^^^^^^^^^^^^^^^^^^^^^^^^^
  File "/usr/local/lib/python3.12/site-packages/asgiref/sync.py", line 489, in thread_handler
    raise exc_info[1]
  File "/usr/local/lib/python3.12/site-packages/django/core/handlers/base.py", line 253, in _get_response_async
    response = await wrapped_callback(
               ^^^^^^^^^^^^^^^^^^^^^^^
  File "/usr/local/lib/python3.12/site-packages/asgiref/sync.py", line 439, in __call__
    ret = await asyncio.shield(exec_coro)
          ^^^^^^^^^^^^^^^^^^^^^^^^^^^^^^^
  File "/usr/local/lib/python3.12/concurrent/futures/thread.py", line 59, in run
    result = self.fn(*self.args, **self.kwargs)
             ^^^^^^^^^^^^^^^^^^^^^^^^^^^^^^^^^^
  File "/usr/local/lib/python3.12/site-packages/asgiref/sync.py", line 493, in thread_handler
    return func(*args, **kwargs)
           ^^^^^^^^^^^^^^^^^^^^^
  File "/usr/local/lib/python3.12/site-packages/django/contrib/admin/options.py", line 719, in wrapper
    return self.admin_site.admin_view(view)(*args, **kwargs)
           ^^^^^^^^^^^^^^^^^^^^^^^^^^^^^^^^^^^^^^^^^^^^^^^^^
  File "/usr/local/lib/python3.12/site-packages/django/utils/decorators.py", line 192, in _view_wrapper
    result = _process_exception(request, e)
             ^^^^^^^^^^^^^^^^^^^^^^^^^^^^^^
  File "/usr/local/lib/python3.12/site-packages/django/utils/decorators.py", line 190, in _view_wrapper
    response = view_func(request, *args, **kwargs)
               ^^^^^^^^^^^^^^^^^^^^^^^^^^^^^^^^^^^
  File "/usr/local/lib/python3.12/site-packages/django/views/decorators/cache.py", line 80, in _view_wrapper
    response = view_func(request, *args, **kwargs)
               ^^^^^^^^^^^^^^^^^^^^^^^^^^^^^^^^^^^
  File "/usr/local/lib/python3.12/site-packages/django/contrib/admin/sites.py", line 246, in inner
    return view(request, *args, **kwargs)
           ^^^^^^^^^^^^^^^^^^^^^^^^^^^^^^
  File "/usr/local/lib/python3.12/site-packages/django/utils/decorators.py", line 48, in _wrapper
    return bound_method(*args, **kwargs)
           ^^^^^^^^^^^^^^^^^^^^^^^^^^^^^
  File "/usr/local/lib/python3.12/site-packages/django/utils/decorators.py", line 192, in _view_wrapper
    result = _process_exception(request, e)
             ^^^^^^^^^^^^^^^^^^^^^^^^^^^^^^
  File "/usr/local/lib/python3.12/site-packages/django/utils/decorators.py", line 190, in _view_wrapper
    response = view_func(request, *args, **kwargs)
               ^^^^^^^^^^^^^^^^^^^^^^^^^^^^^^^^^^^
  File "/usr/local/lib/python3.12/site-packages/django/contrib/admin/options.py", line 2024, in changelist_view
    cl = self.get_changelist_instance(request)
         ^^^^^^^^^^^^^^^^^^^^^^^^^^^^^^^^^^^^^
  File "/usr/local/lib/python3.12/site-packages/django/contrib/admin/options.py", line 867, in get_changelist_instance
    return ChangeList(
           ^^^^^^^^^^^
  File "/usr/local/lib/python3.12/site-packages/django/contrib/admin/views/main.py", line 91, in __init__
    self.root_queryset = model_admin.get_queryset(request)
                         ^^^^^^^^^^^^^^^^^^^^^^^^^^^^^^^^^
  File "/usr/local/lib/python3.12/site-packages/django/contrib/admin/options.py", line 440, in get_queryset
    qs = qs.order_by(*ordering)
         ^^^^^^^^^^^^^^^^^^^^^^
  File "/usr/local/lib/python3.12/site-packages/django/db/models/query.py", line 1708, in order_by
    obj.query.add_ordering(*field_names)
  File "/usr/local/lib/python3.12/site-packages/django/db/models/sql/query.py", line 2288, in add_ordering
    self.names_to_path(item.split(LOOKUP_SEP), self.model._meta)
  File "/usr/local/lib/python3.12/site-packages/django/db/models/sql/query.py", line 1802, in names_to_path
    raise FieldError(
django.core.exceptions.FieldError: Cannot resolve keyword 'username' into field. Choices are: created_at, date_joined, email, first_name, groups, id, is_active, is_staff, is_superuser, last_login, last_name, logentry, password, updated_at, user_permissions
ERROR 2025-08-02 12:14:49,563 log Internal Server Error: /admin/accounts/user/
Traceback (most recent call last):
  File "/usr/local/lib/python3.12/site-packages/asgiref/sync.py", line 489, in thread_handler
    raise exc_info[1]
  File "/usr/local/lib/python3.12/site-packages/django/core/handlers/exception.py", line 42, in inner
    response = await get_response(request)
               ^^^^^^^^^^^^^^^^^^^^^^^^^^^
  File "/usr/local/lib/python3.12/site-packages/asgiref/sync.py", line 489, in thread_handler
    raise exc_info[1]
  File "/usr/local/lib/python3.12/site-packages/django/core/handlers/base.py", line 253, in _get_response_async
    response = await wrapped_callback(
               ^^^^^^^^^^^^^^^^^^^^^^^
  File "/usr/local/lib/python3.12/site-packages/asgiref/sync.py", line 439, in __call__
    ret = await asyncio.shield(exec_coro)
          ^^^^^^^^^^^^^^^^^^^^^^^^^^^^^^^
  File "/usr/local/lib/python3.12/concurrent/futures/thread.py", line 59, in run
    result = self.fn(*self.args, **self.kwargs)
             ^^^^^^^^^^^^^^^^^^^^^^^^^^^^^^^^^^
  File "/usr/local/lib/python3.12/site-packages/asgiref/sync.py", line 493, in thread_handler
    return func(*args, **kwargs)
           ^^^^^^^^^^^^^^^^^^^^^
  File "/usr/local/lib/python3.12/site-packages/django/contrib/admin/options.py", line 719, in wrapper
    return self.admin_site.admin_view(view)(*args, **kwargs)
           ^^^^^^^^^^^^^^^^^^^^^^^^^^^^^^^^^^^^^^^^^^^^^^^^^
  File "/usr/local/lib/python3.12/site-packages/django/utils/decorators.py", line 192, in _view_wrapper
    result = _process_exception(request, e)
             ^^^^^^^^^^^^^^^^^^^^^^^^^^^^^^
  File "/usr/local/lib/python3.12/site-packages/django/utils/decorators.py", line 190, in _view_wrapper
    response = view_func(request, *args, **kwargs)
               ^^^^^^^^^^^^^^^^^^^^^^^^^^^^^^^^^^^
  File "/usr/local/lib/python3.12/site-packages/django/views/decorators/cache.py", line 80, in _view_wrapper
    response = view_func(request, *args, **kwargs)
               ^^^^^^^^^^^^^^^^^^^^^^^^^^^^^^^^^^^
  File "/usr/local/lib/python3.12/site-packages/django/contrib/admin/sites.py", line 246, in inner
    return view(request, *args, **kwargs)
           ^^^^^^^^^^^^^^^^^^^^^^^^^^^^^^
  File "/usr/local/lib/python3.12/site-packages/django/utils/decorators.py", line 48, in _wrapper
    return bound_method(*args, **kwargs)
           ^^^^^^^^^^^^^^^^^^^^^^^^^^^^^
  File "/usr/local/lib/python3.12/site-packages/django/utils/decorators.py", line 192, in _view_wrapper
    result = _process_exception(request, e)
             ^^^^^^^^^^^^^^^^^^^^^^^^^^^^^^
  File "/usr/local/lib/python3.12/site-packages/django/utils/decorators.py", line 190, in _view_wrapper
    response = view_func(request, *args, **kwargs)
               ^^^^^^^^^^^^^^^^^^^^^^^^^^^^^^^^^^^
  File "/usr/local/lib/python3.12/site-packages/django/contrib/admin/options.py", line 2024, in changelist_view
    cl = self.get_changelist_instance(request)
         ^^^^^^^^^^^^^^^^^^^^^^^^^^^^^^^^^^^^^
  File "/usr/local/lib/python3.12/site-packages/django/contrib/admin/options.py", line 867, in get_changelist_instance
    return ChangeList(
           ^^^^^^^^^^^
  File "/usr/local/lib/python3.12/site-packages/django/contrib/admin/views/main.py", line 91, in __init__
    self.root_queryset = model_admin.get_queryset(request)
                         ^^^^^^^^^^^^^^^^^^^^^^^^^^^^^^^^^
  File "/usr/local/lib/python3.12/site-packages/django/contrib/admin/options.py", line 440, in get_queryset
    qs = qs.order_by(*ordering)
         ^^^^^^^^^^^^^^^^^^^^^^
  File "/usr/local/lib/python3.12/site-packages/django/db/models/query.py", line 1708, in order_by
    obj.query.add_ordering(*field_names)
  File "/usr/local/lib/python3.12/site-packages/django/db/models/sql/query.py", line 2288, in add_ordering
    self.names_to_path(item.split(LOOKUP_SEP), self.model._meta)
  File "/usr/local/lib/python3.12/site-packages/django/db/models/sql/query.py", line 1802, in names_to_path
    raise FieldError(
django.core.exceptions.FieldError: Cannot resolve keyword 'username' into field. Choices are: created_at, date_joined, email, first_name, groups, id, is_active, is_staff, is_superuser, last_login, last_name, logentry, password, updated_at, user_permissions
WARNING 2025-08-02 12:27:13,456 log Bad Request: /api/v1/auth/register/
WARNING 2025-08-02 12:27:18,390 log Bad Request: /api/v1/auth/register/
ERROR 2025-08-02 12:27:26,027 log Internal Server Error: /api/v1/auth/register/
Traceback (most recent call last):
  File "/usr/local/lib/python3.12/site-packages/rest_framework/fields.py", line 437, in get_attribute
    return get_attribute(instance, self.source_attrs)
           ^^^^^^^^^^^^^^^^^^^^^^^^^^^^^^^^^^^^^^^^^^
  File "/usr/local/lib/python3.12/site-packages/rest_framework/fields.py", line 104, in get_attribute
    instance = getattr(instance, attr)
               ^^^^^^^^^^^^^^^^^^^^^^^
AttributeError: 'User' object has no attribute 'confirm_password'

During handling of the above exception, another exception occurred:

Traceback (most recent call last):
  File "/usr/local/lib/python3.12/site-packages/asgiref/sync.py", line 489, in thread_handler
    raise exc_info[1]
  File "/usr/local/lib/python3.12/site-packages/django/core/handlers/exception.py", line 42, in inner
    response = await get_response(request)
               ^^^^^^^^^^^^^^^^^^^^^^^^^^^
  File "/usr/local/lib/python3.12/site-packages/asgiref/sync.py", line 489, in thread_handler
    raise exc_info[1]
  File "/usr/local/lib/python3.12/site-packages/django/core/handlers/base.py", line 253, in _get_response_async
    response = await wrapped_callback(
               ^^^^^^^^^^^^^^^^^^^^^^^
  File "/usr/local/lib/python3.12/site-packages/asgiref/sync.py", line 439, in __call__
    ret = await asyncio.shield(exec_coro)
          ^^^^^^^^^^^^^^^^^^^^^^^^^^^^^^^
  File "/usr/local/lib/python3.12/concurrent/futures/thread.py", line 59, in run
    result = self.fn(*self.args, **self.kwargs)
             ^^^^^^^^^^^^^^^^^^^^^^^^^^^^^^^^^^
  File "/usr/local/lib/python3.12/site-packages/asgiref/sync.py", line 493, in thread_handler
    return func(*args, **kwargs)
           ^^^^^^^^^^^^^^^^^^^^^
  File "/usr/local/lib/python3.12/site-packages/django/views/decorators/csrf.py", line 65, in _view_wrapper
    return view_func(request, *args, **kwargs)
           ^^^^^^^^^^^^^^^^^^^^^^^^^^^^^^^^^^^
  File "/usr/local/lib/python3.12/site-packages/django/views/generic/base.py", line 104, in view
    return self.dispatch(request, *args, **kwargs)
           ^^^^^^^^^^^^^^^^^^^^^^^^^^^^^^^^^^^^^^^
  File "/usr/local/lib/python3.12/site-packages/rest_framework/views.py", line 515, in dispatch
    response = self.handle_exception(exc)
               ^^^^^^^^^^^^^^^^^^^^^^^^^^
  File "/usr/local/lib/python3.12/site-packages/rest_framework/views.py", line 475, in handle_exception
    self.raise_uncaught_exception(exc)
  File "/usr/local/lib/python3.12/site-packages/rest_framework/views.py", line 486, in raise_uncaught_exception
    raise exc
  File "/usr/local/lib/python3.12/site-packages/rest_framework/views.py", line 512, in dispatch
    response = handler(request, *args, **kwargs)
               ^^^^^^^^^^^^^^^^^^^^^^^^^^^^^^^^^
  File "/usr/local/lib/python3.12/site-packages/rest_framework/generics.py", line 194, in post
    return self.create(request, *args, **kwargs)
           ^^^^^^^^^^^^^^^^^^^^^^^^^^^^^^^^^^^^^
  File "/usr/local/lib/python3.12/site-packages/rest_framework/mixins.py", line 20, in create
    headers = self.get_success_headers(serializer.data)
                                       ^^^^^^^^^^^^^^^
  File "/usr/local/lib/python3.12/site-packages/rest_framework/serializers.py", line 573, in data
    ret = super().data
          ^^^^^^^^^^^^
  File "/usr/local/lib/python3.12/site-packages/rest_framework/serializers.py", line 251, in data
    self._data = self.to_representation(self.instance)
                 ^^^^^^^^^^^^^^^^^^^^^^^^^^^^^^^^^^^^^
  File "/usr/local/lib/python3.12/site-packages/rest_framework/serializers.py", line 527, in to_representation
    attribute = field.get_attribute(instance)
                ^^^^^^^^^^^^^^^^^^^^^^^^^^^^^
  File "/usr/local/lib/python3.12/site-packages/rest_framework/fields.py", line 470, in get_attribute
    raise type(exc)(msg)
AttributeError: Got AttributeError when attempting to get a value for field `confirm_password` on serializer `RegisterSerializer`.
The serializer field might be named incorrectly and not match any attribute or key on the `User` instance.
Original exception text was: 'User' object has no attribute 'confirm_password'.
ERROR 2025-08-02 12:29:28,370 log Internal Server Error: /api/v1/auth/register/
Traceback (most recent call last):
  File "/usr/local/lib/python3.12/site-packages/asgiref/sync.py", line 489, in thread_handler
    raise exc_info[1]
  File "/usr/local/lib/python3.12/site-packages/django/core/handlers/exception.py", line 42, in inner
    response = await get_response(request)
               ^^^^^^^^^^^^^^^^^^^^^^^^^^^
  File "/usr/local/lib/python3.12/site-packages/asgiref/sync.py", line 489, in thread_handler
    raise exc_info[1]
  File "/usr/local/lib/python3.12/site-packages/django/core/handlers/base.py", line 253, in _get_response_async
    response = await wrapped_callback(
               ^^^^^^^^^^^^^^^^^^^^^^^
  File "/usr/local/lib/python3.12/site-packages/asgiref/sync.py", line 439, in __call__
    ret = await asyncio.shield(exec_coro)
          ^^^^^^^^^^^^^^^^^^^^^^^^^^^^^^^
  File "/usr/local/lib/python3.12/concurrent/futures/thread.py", line 59, in run
    result = self.fn(*self.args, **self.kwargs)
             ^^^^^^^^^^^^^^^^^^^^^^^^^^^^^^^^^^
  File "/usr/local/lib/python3.12/site-packages/asgiref/sync.py", line 493, in thread_handler
    return func(*args, **kwargs)
           ^^^^^^^^^^^^^^^^^^^^^
  File "/usr/local/lib/python3.12/site-packages/django/views/decorators/csrf.py", line 65, in _view_wrapper
    return view_func(request, *args, **kwargs)
           ^^^^^^^^^^^^^^^^^^^^^^^^^^^^^^^^^^^
  File "/usr/local/lib/python3.12/site-packages/django/views/generic/base.py", line 104, in view
    return self.dispatch(request, *args, **kwargs)
           ^^^^^^^^^^^^^^^^^^^^^^^^^^^^^^^^^^^^^^^
  File "/usr/local/lib/python3.12/site-packages/rest_framework/views.py", line 517, in dispatch
    self.response = self.finalize_response(request, response, *args, **kwargs)
                    ^^^^^^^^^^^^^^^^^^^^^^^^^^^^^^^^^^^^^^^^^^^^^^^^^^^^^^^^^^
  File "/usr/local/lib/python3.12/site-packages/rest_framework/views.py", line 429, in finalize_response
    assert isinstance(response, HttpResponseBase), (
           ^^^^^^^^^^^^^^^^^^^^^^^^^^^^^^^^^^^^^^
AssertionError: Expected a `Response`, `HttpResponse` or `StreamingHttpResponse` to be returned from the view, but received a `<class 'NoneType'>`
WARNING 2025-08-02 12:29:43,172 log Bad Request: /api/v1/auth/register/
ERROR 2025-08-02 13:09:30,239 log Internal Server Error: /admin/cars/brand/
Traceback (most recent call last):
  File "/usr/local/lib/python3.12/site-packages/django/db/backends/utils.py", line 105, in _execute
    return self.cursor.execute(sql, params)
           ^^^^^^^^^^^^^^^^^^^^^^^^^^^^^^^^
psycopg2.errors.UndefinedTable: relation "cars_brand" does not exist
LINE 1: SELECT COUNT(*) AS "__count" FROM "cars_brand"
                                          ^


The above exception was the direct cause of the following exception:

Traceback (most recent call last):
  File "/usr/local/lib/python3.12/site-packages/asgiref/sync.py", line 489, in thread_handler
    raise exc_info[1]
  File "/usr/local/lib/python3.12/site-packages/django/core/handlers/exception.py", line 42, in inner
    response = await get_response(request)
               ^^^^^^^^^^^^^^^^^^^^^^^^^^^
  File "/usr/local/lib/python3.12/site-packages/asgiref/sync.py", line 489, in thread_handler
    raise exc_info[1]
  File "/usr/local/lib/python3.12/site-packages/django/core/handlers/base.py", line 253, in _get_response_async
    response = await wrapped_callback(
               ^^^^^^^^^^^^^^^^^^^^^^^
  File "/usr/local/lib/python3.12/site-packages/asgiref/sync.py", line 439, in __call__
    ret = await asyncio.shield(exec_coro)
          ^^^^^^^^^^^^^^^^^^^^^^^^^^^^^^^
  File "/usr/local/lib/python3.12/concurrent/futures/thread.py", line 59, in run
    result = self.fn(*self.args, **self.kwargs)
             ^^^^^^^^^^^^^^^^^^^^^^^^^^^^^^^^^^
  File "/usr/local/lib/python3.12/site-packages/asgiref/sync.py", line 493, in thread_handler
    return func(*args, **kwargs)
           ^^^^^^^^^^^^^^^^^^^^^
  File "/usr/local/lib/python3.12/site-packages/django/contrib/admin/options.py", line 719, in wrapper
    return self.admin_site.admin_view(view)(*args, **kwargs)
           ^^^^^^^^^^^^^^^^^^^^^^^^^^^^^^^^^^^^^^^^^^^^^^^^^
  File "/usr/local/lib/python3.12/site-packages/django/utils/decorators.py", line 192, in _view_wrapper
    result = _process_exception(request, e)
             ^^^^^^^^^^^^^^^^^^^^^^^^^^^^^^
  File "/usr/local/lib/python3.12/site-packages/django/utils/decorators.py", line 190, in _view_wrapper
    response = view_func(request, *args, **kwargs)
               ^^^^^^^^^^^^^^^^^^^^^^^^^^^^^^^^^^^
  File "/usr/local/lib/python3.12/site-packages/django/views/decorators/cache.py", line 80, in _view_wrapper
    response = view_func(request, *args, **kwargs)
               ^^^^^^^^^^^^^^^^^^^^^^^^^^^^^^^^^^^
  File "/usr/local/lib/python3.12/site-packages/django/contrib/admin/sites.py", line 246, in inner
    return view(request, *args, **kwargs)
           ^^^^^^^^^^^^^^^^^^^^^^^^^^^^^^
  File "/usr/local/lib/python3.12/site-packages/django/utils/decorators.py", line 48, in _wrapper
    return bound_method(*args, **kwargs)
           ^^^^^^^^^^^^^^^^^^^^^^^^^^^^^
  File "/usr/local/lib/python3.12/site-packages/django/utils/decorators.py", line 192, in _view_wrapper
    result = _process_exception(request, e)
             ^^^^^^^^^^^^^^^^^^^^^^^^^^^^^^
  File "/usr/local/lib/python3.12/site-packages/django/utils/decorators.py", line 190, in _view_wrapper
    response = view_func(request, *args, **kwargs)
               ^^^^^^^^^^^^^^^^^^^^^^^^^^^^^^^^^^^
  File "/usr/local/lib/python3.12/site-packages/django/contrib/admin/options.py", line 2024, in changelist_view
    cl = self.get_changelist_instance(request)
         ^^^^^^^^^^^^^^^^^^^^^^^^^^^^^^^^^^^^^
  File "/usr/local/lib/python3.12/site-packages/django/contrib/admin/options.py", line 867, in get_changelist_instance
    return ChangeList(
           ^^^^^^^^^^^
  File "/usr/local/lib/python3.12/site-packages/django/contrib/admin/views/main.py", line 146, in __init__
    self.get_results(request)
  File "/usr/local/lib/python3.12/site-packages/django/contrib/admin/views/main.py", line 313, in get_results
    result_count = paginator.count
                   ^^^^^^^^^^^^^^^
  File "/usr/local/lib/python3.12/site-packages/django/utils/functional.py", line 47, in __get__
    res = instance.__dict__[self.name] = self.func(instance)
                                         ^^^^^^^^^^^^^^^^^^^
  File "/usr/local/lib/python3.12/site-packages/django/core/paginator.py", line 110, in count
    return c()
           ^^^
  File "/usr/local/lib/python3.12/site-packages/django/db/models/query.py", line 604, in count
    return self.query.get_count(using=self.db)
           ^^^^^^^^^^^^^^^^^^^^^^^^^^^^^^^^^^^
  File "/usr/local/lib/python3.12/site-packages/django/db/models/sql/query.py", line 644, in get_count
    return obj.get_aggregation(using, {"__count": Count("*")})["__count"]
           ^^^^^^^^^^^^^^^^^^^^^^^^^^^^^^^^^^^^^^^^^^^^^^^^^^^
  File "/usr/local/lib/python3.12/site-packages/django/db/models/sql/query.py", line 626, in get_aggregation
    result = compiler.execute_sql(SINGLE)
             ^^^^^^^^^^^^^^^^^^^^^^^^^^^^
  File "/usr/local/lib/python3.12/site-packages/django/db/models/sql/compiler.py", line 1622, in execute_sql
    cursor.execute(sql, params)
  File "/usr/local/lib/python3.12/site-packages/django/db/backends/utils.py", line 122, in execute
    return super().execute(sql, params)
           ^^^^^^^^^^^^^^^^^^^^^^^^^^^^
  File "/usr/local/lib/python3.12/site-packages/django/db/backends/utils.py", line 79, in execute
    return self._execute_with_wrappers(
           ^^^^^^^^^^^^^^^^^^^^^^^^^^^^
  File "/usr/local/lib/python3.12/site-packages/django/db/backends/utils.py", line 92, in _execute_with_wrappers
    return executor(sql, params, many, context)
           ^^^^^^^^^^^^^^^^^^^^^^^^^^^^^^^^^^^^
  File "/usr/local/lib/python3.12/site-packages/django/db/backends/utils.py", line 100, in _execute
    with self.db.wrap_database_errors:
         ^^^^^^^^^^^^^^^^^^^^^^^^^^^^
  File "/usr/local/lib/python3.12/site-packages/django/db/utils.py", line 91, in __exit__
    raise dj_exc_value.with_traceback(traceback) from exc_value
  File "/usr/local/lib/python3.12/site-packages/django/db/backends/utils.py", line 105, in _execute
    return self.cursor.execute(sql, params)
           ^^^^^^^^^^^^^^^^^^^^^^^^^^^^^^^^
django.db.utils.ProgrammingError: relation "cars_brand" does not exist
LINE 1: SELECT COUNT(*) AS "__count" FROM "cars_brand"
                                          ^

ERROR 2025-08-02 13:49:08,576 log Internal Server Error: /admin/cars/transmission/
Traceback (most recent call last):
  File "/usr/local/lib/python3.12/site-packages/django/db/backends/utils.py", line 105, in _execute
    return self.cursor.execute(sql, params)
           ^^^^^^^^^^^^^^^^^^^^^^^^^^^^^^^^
psycopg2.errors.UndefinedTable: relation "cars_transmission" does not exist
LINE 1: SELECT COUNT(*) AS "__count" FROM "cars_transmission"
                                          ^


The above exception was the direct cause of the following exception:

Traceback (most recent call last):
  File "/usr/local/lib/python3.12/site-packages/asgiref/sync.py", line 489, in thread_handler
    raise exc_info[1]
  File "/usr/local/lib/python3.12/site-packages/django/core/handlers/exception.py", line 42, in inner
    response = await get_response(request)
               ^^^^^^^^^^^^^^^^^^^^^^^^^^^
  File "/usr/local/lib/python3.12/site-packages/asgiref/sync.py", line 489, in thread_handler
    raise exc_info[1]
  File "/usr/local/lib/python3.12/site-packages/django/core/handlers/base.py", line 253, in _get_response_async
    response = await wrapped_callback(
               ^^^^^^^^^^^^^^^^^^^^^^^
  File "/usr/local/lib/python3.12/site-packages/asgiref/sync.py", line 439, in __call__
    ret = await asyncio.shield(exec_coro)
          ^^^^^^^^^^^^^^^^^^^^^^^^^^^^^^^
  File "/usr/local/lib/python3.12/concurrent/futures/thread.py", line 59, in run
    result = self.fn(*self.args, **self.kwargs)
             ^^^^^^^^^^^^^^^^^^^^^^^^^^^^^^^^^^
  File "/usr/local/lib/python3.12/site-packages/asgiref/sync.py", line 493, in thread_handler
    return func(*args, **kwargs)
           ^^^^^^^^^^^^^^^^^^^^^
  File "/usr/local/lib/python3.12/site-packages/django/contrib/admin/options.py", line 719, in wrapper
    return self.admin_site.admin_view(view)(*args, **kwargs)
           ^^^^^^^^^^^^^^^^^^^^^^^^^^^^^^^^^^^^^^^^^^^^^^^^^
  File "/usr/local/lib/python3.12/site-packages/django/utils/decorators.py", line 192, in _view_wrapper
    result = _process_exception(request, e)
             ^^^^^^^^^^^^^^^^^^^^^^^^^^^^^^
  File "/usr/local/lib/python3.12/site-packages/django/utils/decorators.py", line 190, in _view_wrapper
    response = view_func(request, *args, **kwargs)
               ^^^^^^^^^^^^^^^^^^^^^^^^^^^^^^^^^^^
  File "/usr/local/lib/python3.12/site-packages/django/views/decorators/cache.py", line 80, in _view_wrapper
    response = view_func(request, *args, **kwargs)
               ^^^^^^^^^^^^^^^^^^^^^^^^^^^^^^^^^^^
  File "/usr/local/lib/python3.12/site-packages/django/contrib/admin/sites.py", line 246, in inner
    return view(request, *args, **kwargs)
           ^^^^^^^^^^^^^^^^^^^^^^^^^^^^^^
  File "/usr/local/lib/python3.12/site-packages/django/utils/decorators.py", line 48, in _wrapper
    return bound_method(*args, **kwargs)
           ^^^^^^^^^^^^^^^^^^^^^^^^^^^^^
  File "/usr/local/lib/python3.12/site-packages/django/utils/decorators.py", line 192, in _view_wrapper
    result = _process_exception(request, e)
             ^^^^^^^^^^^^^^^^^^^^^^^^^^^^^^
  File "/usr/local/lib/python3.12/site-packages/django/utils/decorators.py", line 190, in _view_wrapper
    response = view_func(request, *args, **kwargs)
               ^^^^^^^^^^^^^^^^^^^^^^^^^^^^^^^^^^^
  File "/usr/local/lib/python3.12/site-packages/django/contrib/admin/options.py", line 2024, in changelist_view
    cl = self.get_changelist_instance(request)
         ^^^^^^^^^^^^^^^^^^^^^^^^^^^^^^^^^^^^^
  File "/usr/local/lib/python3.12/site-packages/django/contrib/admin/options.py", line 867, in get_changelist_instance
    return ChangeList(
           ^^^^^^^^^^^
  File "/usr/local/lib/python3.12/site-packages/django/contrib/admin/views/main.py", line 146, in __init__
    self.get_results(request)
  File "/usr/local/lib/python3.12/site-packages/django/contrib/admin/views/main.py", line 313, in get_results
    result_count = paginator.count
                   ^^^^^^^^^^^^^^^
  File "/usr/local/lib/python3.12/site-packages/django/utils/functional.py", line 47, in __get__
    res = instance.__dict__[self.name] = self.func(instance)
                                         ^^^^^^^^^^^^^^^^^^^
  File "/usr/local/lib/python3.12/site-packages/django/core/paginator.py", line 110, in count
    return c()
           ^^^
  File "/usr/local/lib/python3.12/site-packages/django/db/models/query.py", line 604, in count
    return self.query.get_count(using=self.db)
           ^^^^^^^^^^^^^^^^^^^^^^^^^^^^^^^^^^^
  File "/usr/local/lib/python3.12/site-packages/django/db/models/sql/query.py", line 644, in get_count
    return obj.get_aggregation(using, {"__count": Count("*")})["__count"]
           ^^^^^^^^^^^^^^^^^^^^^^^^^^^^^^^^^^^^^^^^^^^^^^^^^^^
  File "/usr/local/lib/python3.12/site-packages/django/db/models/sql/query.py", line 626, in get_aggregation
    result = compiler.execute_sql(SINGLE)
             ^^^^^^^^^^^^^^^^^^^^^^^^^^^^
  File "/usr/local/lib/python3.12/site-packages/django/db/models/sql/compiler.py", line 1622, in execute_sql
    cursor.execute(sql, params)
  File "/usr/local/lib/python3.12/site-packages/django/db/backends/utils.py", line 122, in execute
    return super().execute(sql, params)
           ^^^^^^^^^^^^^^^^^^^^^^^^^^^^
  File "/usr/local/lib/python3.12/site-packages/django/db/backends/utils.py", line 79, in execute
    return self._execute_with_wrappers(
           ^^^^^^^^^^^^^^^^^^^^^^^^^^^^
  File "/usr/local/lib/python3.12/site-packages/django/db/backends/utils.py", line 92, in _execute_with_wrappers
    return executor(sql, params, many, context)
           ^^^^^^^^^^^^^^^^^^^^^^^^^^^^^^^^^^^^
  File "/usr/local/lib/python3.12/site-packages/django/db/backends/utils.py", line 100, in _execute
    with self.db.wrap_database_errors:
         ^^^^^^^^^^^^^^^^^^^^^^^^^^^^
  File "/usr/local/lib/python3.12/site-packages/django/db/utils.py", line 91, in __exit__
    raise dj_exc_value.with_traceback(traceback) from exc_value
  File "/usr/local/lib/python3.12/site-packages/django/db/backends/utils.py", line 105, in _execute
    return self.cursor.execute(sql, params)
           ^^^^^^^^^^^^^^^^^^^^^^^^^^^^^^^^
django.db.utils.ProgrammingError: relation "cars_transmission" does not exist
LINE 1: SELECT COUNT(*) AS "__count" FROM "cars_transmission"
                                          ^

ERROR 2025-08-02 15:02:00,283 log Internal Server Error: /admin/cars/car/
Traceback (most recent call last):
  File "/usr/local/lib/python3.12/site-packages/django/db/models/options.py", line 683, in get_field
    return self.fields_map[field_name]
           ~~~~~~~~~~~~~~~^^^^^^^^^^^^
KeyError: ''

During handling of the above exception, another exception occurred:

Traceback (most recent call last):
  File "/usr/local/lib/python3.12/site-packages/asgiref/sync.py", line 489, in thread_handler
    raise exc_info[1]
  File "/usr/local/lib/python3.12/site-packages/django/core/handlers/exception.py", line 42, in inner
    response = await get_response(request)
               ^^^^^^^^^^^^^^^^^^^^^^^^^^^
  File "/usr/local/lib/python3.12/site-packages/asgiref/sync.py", line 489, in thread_handler
    raise exc_info[1]
  File "/usr/local/lib/python3.12/site-packages/django/core/handlers/base.py", line 253, in _get_response_async
    response = await wrapped_callback(
               ^^^^^^^^^^^^^^^^^^^^^^^
  File "/usr/local/lib/python3.12/site-packages/asgiref/sync.py", line 439, in __call__
    ret = await asyncio.shield(exec_coro)
          ^^^^^^^^^^^^^^^^^^^^^^^^^^^^^^^
  File "/usr/local/lib/python3.12/concurrent/futures/thread.py", line 59, in run
    result = self.fn(*self.args, **self.kwargs)
             ^^^^^^^^^^^^^^^^^^^^^^^^^^^^^^^^^^
  File "/usr/local/lib/python3.12/site-packages/asgiref/sync.py", line 493, in thread_handler
    return func(*args, **kwargs)
           ^^^^^^^^^^^^^^^^^^^^^
  File "/usr/local/lib/python3.12/site-packages/django/contrib/admin/options.py", line 719, in wrapper
    return self.admin_site.admin_view(view)(*args, **kwargs)
           ^^^^^^^^^^^^^^^^^^^^^^^^^^^^^^^^^^^^^^^^^^^^^^^^^
  File "/usr/local/lib/python3.12/site-packages/django/utils/decorators.py", line 192, in _view_wrapper
    result = _process_exception(request, e)
             ^^^^^^^^^^^^^^^^^^^^^^^^^^^^^^
  File "/usr/local/lib/python3.12/site-packages/django/utils/decorators.py", line 190, in _view_wrapper
    response = view_func(request, *args, **kwargs)
               ^^^^^^^^^^^^^^^^^^^^^^^^^^^^^^^^^^^
  File "/usr/local/lib/python3.12/site-packages/django/views/decorators/cache.py", line 80, in _view_wrapper
    response = view_func(request, *args, **kwargs)
               ^^^^^^^^^^^^^^^^^^^^^^^^^^^^^^^^^^^
  File "/usr/local/lib/python3.12/site-packages/django/contrib/admin/sites.py", line 246, in inner
    return view(request, *args, **kwargs)
           ^^^^^^^^^^^^^^^^^^^^^^^^^^^^^^
  File "/usr/local/lib/python3.12/site-packages/django/utils/decorators.py", line 48, in _wrapper
    return bound_method(*args, **kwargs)
           ^^^^^^^^^^^^^^^^^^^^^^^^^^^^^
  File "/usr/local/lib/python3.12/site-packages/django/utils/decorators.py", line 192, in _view_wrapper
    result = _process_exception(request, e)
             ^^^^^^^^^^^^^^^^^^^^^^^^^^^^^^
  File "/usr/local/lib/python3.12/site-packages/django/utils/decorators.py", line 190, in _view_wrapper
    response = view_func(request, *args, **kwargs)
               ^^^^^^^^^^^^^^^^^^^^^^^^^^^^^^^^^^^
  File "/usr/local/lib/python3.12/site-packages/django/contrib/admin/options.py", line 2024, in changelist_view
    cl = self.get_changelist_instance(request)
         ^^^^^^^^^^^^^^^^^^^^^^^^^^^^^^^^^^^^^
  File "/usr/local/lib/python3.12/site-packages/django/contrib/admin/options.py", line 867, in get_changelist_instance
    return ChangeList(
           ^^^^^^^^^^^
  File "/usr/local/lib/python3.12/site-packages/django/contrib/admin/views/main.py", line 145, in __init__
    self.queryset = self.get_queryset(request)
                    ^^^^^^^^^^^^^^^^^^^^^^^^^^
  File "/usr/local/lib/python3.12/site-packages/django/contrib/admin/views/main.py", line 545, in get_queryset
    ) = self.get_filters(request)
        ^^^^^^^^^^^^^^^^^^^^^^^^^
  File "/usr/local/lib/python3.12/site-packages/django/contrib/admin/views/main.py", line 214, in get_filters
    field = get_fields_from_path(self.model, field_path)[-1]
            ^^^^^^^^^^^^^^^^^^^^^^^^^^^^^^^^^^^^^^^^^^^^
  File "/usr/local/lib/python3.12/site-packages/django/contrib/admin/utils.py", line 547, in get_fields_from_path
    fields.append(parent._meta.get_field(piece))
                  ^^^^^^^^^^^^^^^^^^^^^^^^^^^^^
  File "/usr/local/lib/python3.12/site-packages/django/db/models/options.py", line 685, in get_field
    raise FieldDoesNotExist(
django.core.exceptions.FieldDoesNotExist: Car has no field named ''
ERROR 2025-08-02 15:09:03,755 log Internal Server Error: /api/v1/cars/car/list/
Traceback (most recent call last):
  File "/usr/local/lib/python3.12/site-packages/asgiref/sync.py", line 489, in thread_handler
    raise exc_info[1]
  File "/usr/local/lib/python3.12/site-packages/django/core/handlers/exception.py", line 42, in inner
    response = await get_response(request)
               ^^^^^^^^^^^^^^^^^^^^^^^^^^^
  File "/usr/local/lib/python3.12/site-packages/asgiref/sync.py", line 489, in thread_handler
    raise exc_info[1]
  File "/usr/local/lib/python3.12/site-packages/django/core/handlers/base.py", line 253, in _get_response_async
    response = await wrapped_callback(
               ^^^^^^^^^^^^^^^^^^^^^^^
  File "/usr/local/lib/python3.12/site-packages/asgiref/sync.py", line 439, in __call__
    ret = await asyncio.shield(exec_coro)
          ^^^^^^^^^^^^^^^^^^^^^^^^^^^^^^^
  File "/usr/local/lib/python3.12/concurrent/futures/thread.py", line 59, in run
    result = self.fn(*self.args, **self.kwargs)
             ^^^^^^^^^^^^^^^^^^^^^^^^^^^^^^^^^^
  File "/usr/local/lib/python3.12/site-packages/asgiref/sync.py", line 493, in thread_handler
    return func(*args, **kwargs)
           ^^^^^^^^^^^^^^^^^^^^^
  File "/usr/local/lib/python3.12/site-packages/django/views/decorators/csrf.py", line 65, in _view_wrapper
    return view_func(request, *args, **kwargs)
           ^^^^^^^^^^^^^^^^^^^^^^^^^^^^^^^^^^^
  File "/usr/local/lib/python3.12/site-packages/django/views/generic/base.py", line 104, in view
    return self.dispatch(request, *args, **kwargs)
           ^^^^^^^^^^^^^^^^^^^^^^^^^^^^^^^^^^^^^^^
  File "/usr/local/lib/python3.12/site-packages/rest_framework/views.py", line 515, in dispatch
    response = self.handle_exception(exc)
               ^^^^^^^^^^^^^^^^^^^^^^^^^^
  File "/usr/local/lib/python3.12/site-packages/rest_framework/views.py", line 475, in handle_exception
    self.raise_uncaught_exception(exc)
  File "/usr/local/lib/python3.12/site-packages/rest_framework/views.py", line 486, in raise_uncaught_exception
    raise exc
  File "/usr/local/lib/python3.12/site-packages/rest_framework/views.py", line 512, in dispatch
    response = handler(request, *args, **kwargs)
               ^^^^^^^^^^^^^^^^^^^^^^^^^^^^^^^^^
  File "/usr/local/lib/python3.12/site-packages/rest_framework/generics.py", line 203, in get
    return self.list(request, *args, **kwargs)
           ^^^^^^^^^^^^^^^^^^^^^^^^^^^^^^^^^^^
  File "/usr/local/lib/python3.12/site-packages/rest_framework/mixins.py", line 46, in list
    return Response(serializer.data)
                    ^^^^^^^^^^^^^^^
  File "/usr/local/lib/python3.12/site-packages/rest_framework/serializers.py", line 797, in data
    ret = super().data
          ^^^^^^^^^^^^
  File "/usr/local/lib/python3.12/site-packages/rest_framework/serializers.py", line 251, in data
    self._data = self.to_representation(self.instance)
                 ^^^^^^^^^^^^^^^^^^^^^^^^^^^^^^^^^^^^^
  File "/usr/local/lib/python3.12/site-packages/rest_framework/serializers.py", line 716, in to_representation
    self.child.to_representation(item) for item in iterable
    ^^^^^^^^^^^^^^^^^^^^^^^^^^^^^^^^^^
  File "/usr/local/lib/python3.12/site-packages/rest_framework/serializers.py", line 525, in to_representation
    for field in fields:
                 ^^^^^^
  File "/usr/local/lib/python3.12/site-packages/rest_framework/serializers.py", line 386, in _readable_fields
    for field in self.fields.values():
                 ^^^^^^^^^^^
  File "/usr/local/lib/python3.12/site-packages/django/utils/functional.py", line 47, in __get__
    res = instance.__dict__[self.name] = self.func(instance)
                                         ^^^^^^^^^^^^^^^^^^^
  File "/usr/local/lib/python3.12/site-packages/rest_framework/serializers.py", line 374, in fields
    for key, value in self.get_fields().items():
                      ^^^^^^^^^^^^^^^^^
  File "/usr/local/lib/python3.12/site-packages/rest_framework/serializers.py", line 1105, in get_fields
    field_class, field_kwargs = self.build_field(
                                ^^^^^^^^^^^^^^^^^
  File "/usr/local/lib/python3.12/site-packages/rest_framework/serializers.py", line 1251, in build_field
    return self.build_unknown_field(field_name, model_class)
           ^^^^^^^^^^^^^^^^^^^^^^^^^^^^^^^^^^^^^^^^^^^^^^^^^
  File "/usr/local/lib/python3.12/site-packages/rest_framework/serializers.py", line 1369, in build_unknown_field
    raise ImproperlyConfigured(
django.core.exceptions.ImproperlyConfigured: Field name `date` is not valid for model `Car` in `core.apps.cars.serializers.car.CarListSerializer`.
ERROR 2025-08-02 15:12:50,175 log Internal Server Error: /admin/cars/car/
Traceback (most recent call last):
  File "/usr/local/lib/python3.12/site-packages/django/db/models/options.py", line 683, in get_field
    return self.fields_map[field_name]
           ~~~~~~~~~~~~~~~^^^^^^^^^^^^
KeyError: 'action_checkbox'

During handling of the above exception, another exception occurred:

Traceback (most recent call last):
  File "/usr/local/lib/python3.12/site-packages/django/contrib/admin/utils.py", line 290, in lookup_field
    f = _get_non_gfk_field(opts, name)
        ^^^^^^^^^^^^^^^^^^^^^^^^^^^^^^
  File "/usr/local/lib/python3.12/site-packages/django/contrib/admin/utils.py", line 330, in _get_non_gfk_field
    field = opts.get_field(name)
            ^^^^^^^^^^^^^^^^^^^^
  File "/usr/local/lib/python3.12/site-packages/django/db/models/options.py", line 685, in get_field
    raise FieldDoesNotExist(
django.core.exceptions.FieldDoesNotExist: Car has no field named 'action_checkbox'

During handling of the above exception, another exception occurred:

Traceback (most recent call last):
  File "/usr/local/lib/python3.12/site-packages/asgiref/sync.py", line 489, in thread_handler
    raise exc_info[1]
  File "/usr/local/lib/python3.12/site-packages/django/core/handlers/exception.py", line 42, in inner
    response = await get_response(request)
               ^^^^^^^^^^^^^^^^^^^^^^^^^^^
  File "/usr/local/lib/python3.12/site-packages/asgiref/sync.py", line 489, in thread_handler
    raise exc_info[1]
  File "/usr/local/lib/python3.12/site-packages/django/core/handlers/base.py", line 284, in _get_response_async
    response = await sync_to_async(
               ^^^^^^^^^^^^^^^^^^^^
  File "/usr/local/lib/python3.12/site-packages/asgiref/sync.py", line 439, in __call__
    ret = await asyncio.shield(exec_coro)
          ^^^^^^^^^^^^^^^^^^^^^^^^^^^^^^^
  File "/usr/local/lib/python3.12/concurrent/futures/thread.py", line 59, in run
    result = self.fn(*self.args, **self.kwargs)
             ^^^^^^^^^^^^^^^^^^^^^^^^^^^^^^^^^^
  File "/usr/local/lib/python3.12/site-packages/asgiref/sync.py", line 493, in thread_handler
    return func(*args, **kwargs)
           ^^^^^^^^^^^^^^^^^^^^^
  File "/usr/local/lib/python3.12/site-packages/django/template/response.py", line 114, in render
    self.content = self.rendered_content
                   ^^^^^^^^^^^^^^^^^^^^^
  File "/usr/local/lib/python3.12/site-packages/django/template/response.py", line 92, in rendered_content
    return template.render(context, self._request)
           ^^^^^^^^^^^^^^^^^^^^^^^^^^^^^^^^^^^^^^^
  File "/usr/local/lib/python3.12/site-packages/django/template/backends/django.py", line 107, in render
    return self.template.render(context)
           ^^^^^^^^^^^^^^^^^^^^^^^^^^^^^
  File "/usr/local/lib/python3.12/site-packages/django/template/base.py", line 171, in render
    return self._render(context)
           ^^^^^^^^^^^^^^^^^^^^^
  File "/usr/local/lib/python3.12/site-packages/django/template/base.py", line 163, in _render
    return self.nodelist.render(context)
           ^^^^^^^^^^^^^^^^^^^^^^^^^^^^^
  File "/usr/local/lib/python3.12/site-packages/django/template/base.py", line 1016, in render
    return SafeString("".join([node.render_annotated(context) for node in self]))
                               ^^^^^^^^^^^^^^^^^^^^^^^^^^^^^^
  File "/usr/local/lib/python3.12/site-packages/django/template/base.py", line 977, in render_annotated
    return self.render(context)
           ^^^^^^^^^^^^^^^^^^^^
  File "/usr/local/lib/python3.12/site-packages/django/template/loader_tags.py", line 159, in render
    return compiled_parent._render(context)
           ^^^^^^^^^^^^^^^^^^^^^^^^^^^^^^^^
  File "/usr/local/lib/python3.12/site-packages/django/template/base.py", line 163, in _render
    return self.nodelist.render(context)
           ^^^^^^^^^^^^^^^^^^^^^^^^^^^^^
  File "/usr/local/lib/python3.12/site-packages/django/template/base.py", line 1016, in render
    return SafeString("".join([node.render_annotated(context) for node in self]))
                               ^^^^^^^^^^^^^^^^^^^^^^^^^^^^^^
  File "/usr/local/lib/python3.12/site-packages/django/template/base.py", line 977, in render_annotated
    return self.render(context)
           ^^^^^^^^^^^^^^^^^^^^
  File "/usr/local/lib/python3.12/site-packages/django/template/loader_tags.py", line 159, in render
    return compiled_parent._render(context)
           ^^^^^^^^^^^^^^^^^^^^^^^^^^^^^^^^
  File "/usr/local/lib/python3.12/site-packages/django/template/base.py", line 163, in _render
    return self.nodelist.render(context)
           ^^^^^^^^^^^^^^^^^^^^^^^^^^^^^
  File "/usr/local/lib/python3.12/site-packages/django/template/base.py", line 1016, in render
    return SafeString("".join([node.render_annotated(context) for node in self]))
                               ^^^^^^^^^^^^^^^^^^^^^^^^^^^^^^
  File "/usr/local/lib/python3.12/site-packages/django/template/base.py", line 977, in render_annotated
    return self.render(context)
           ^^^^^^^^^^^^^^^^^^^^
  File "/usr/local/lib/python3.12/site-packages/django/template/loader_tags.py", line 65, in render
    result = block.nodelist.render(context)
             ^^^^^^^^^^^^^^^^^^^^^^^^^^^^^^
  File "/usr/local/lib/python3.12/site-packages/django/template/base.py", line 1016, in render
    return SafeString("".join([node.render_annotated(context) for node in self]))
                               ^^^^^^^^^^^^^^^^^^^^^^^^^^^^^^
  File "/usr/local/lib/python3.12/site-packages/django/template/base.py", line 977, in render_annotated
    return self.render(context)
           ^^^^^^^^^^^^^^^^^^^^
  File "/usr/local/lib/python3.12/site-packages/django/template/loader_tags.py", line 65, in render
    result = block.nodelist.render(context)
             ^^^^^^^^^^^^^^^^^^^^^^^^^^^^^^
  File "/usr/local/lib/python3.12/site-packages/django/template/base.py", line 1016, in render
    return SafeString("".join([node.render_annotated(context) for node in self]))
                               ^^^^^^^^^^^^^^^^^^^^^^^^^^^^^^
  File "/usr/local/lib/python3.12/site-packages/django/template/base.py", line 977, in render_annotated
    return self.render(context)
           ^^^^^^^^^^^^^^^^^^^^
  File "/usr/local/lib/python3.12/site-packages/django/template/loader_tags.py", line 65, in render
    result = block.nodelist.render(context)
             ^^^^^^^^^^^^^^^^^^^^^^^^^^^^^^
  File "/usr/local/lib/python3.12/site-packages/django/template/base.py", line 1016, in render
    return SafeString("".join([node.render_annotated(context) for node in self]))
                               ^^^^^^^^^^^^^^^^^^^^^^^^^^^^^^
  File "/usr/local/lib/python3.12/site-packages/django/template/base.py", line 977, in render_annotated
    return self.render(context)
           ^^^^^^^^^^^^^^^^^^^^
  File "/usr/local/lib/python3.12/site-packages/django/contrib/admin/templatetags/base.py", line 45, in render
    return super().render(context)
           ^^^^^^^^^^^^^^^^^^^^^^^
  File "/usr/local/lib/python3.12/site-packages/django/template/library.py", line 359, in render
    _dict = self.func(*resolved_args, **resolved_kwargs)
            ^^^^^^^^^^^^^^^^^^^^^^^^^^^^^^^^^^^^^^^^^^^^
  File "/usr/local/lib/python3.12/site-packages/django/contrib/admin/templatetags/admin_list.py", line 354, in result_list
    "results": list(results(cl)),
               ^^^^^^^^^^^^^^^^^
  File "/usr/local/lib/python3.12/site-packages/django/contrib/admin/templatetags/admin_list.py", line 330, in results
    yield ResultList(None, items_for_result(cl, res, None))
          ^^^^^^^^^^^^^^^^^^^^^^^^^^^^^^^^^^^^^^^^^^^^^^^^^
  File "/usr/local/lib/python3.12/site-packages/django/contrib/admin/templatetags/admin_list.py", line 321, in __init__
    super().__init__(*items)
  File "/usr/local/lib/python3.12/site-packages/django/contrib/admin/templatetags/admin_list.py", line 219, in items_for_result
    f, attr, value = lookup_field(field_name, result, cl.model_admin)
                     ^^^^^^^^^^^^^^^^^^^^^^^^^^^^^^^^^^^^^^^^^^^^^^^^
  File "/usr/local/lib/python3.12/site-packages/django/contrib/admin/utils.py", line 299, in lookup_field
    value = attr(obj)
            ^^^^^^^^^
  File "/usr/local/lib/python3.12/site-packages/django/contrib/admin/options.py", line 1031, in action_checkbox
    _("Select this object for an action - {}"), str(obj)
                                                ^^^^^^^^
  File "/code/core/apps/cars/models/car.py", line 24, in __str__
    return f'car {self.date}, price {self.price}rubl'
                  ^^^^^^^^^
AttributeError: 'Car' object has no attribute 'date'
ERROR 2025-08-02 15:12:53,054 log Internal Server Error: /admin/cars/car/
Traceback (most recent call last):
  File "/usr/local/lib/python3.12/site-packages/django/db/models/options.py", line 683, in get_field
    return self.fields_map[field_name]
           ~~~~~~~~~~~~~~~^^^^^^^^^^^^
KeyError: 'action_checkbox'

During handling of the above exception, another exception occurred:

Traceback (most recent call last):
  File "/usr/local/lib/python3.12/site-packages/django/contrib/admin/utils.py", line 290, in lookup_field
    f = _get_non_gfk_field(opts, name)
        ^^^^^^^^^^^^^^^^^^^^^^^^^^^^^^
  File "/usr/local/lib/python3.12/site-packages/django/contrib/admin/utils.py", line 330, in _get_non_gfk_field
    field = opts.get_field(name)
            ^^^^^^^^^^^^^^^^^^^^
  File "/usr/local/lib/python3.12/site-packages/django/db/models/options.py", line 685, in get_field
    raise FieldDoesNotExist(
django.core.exceptions.FieldDoesNotExist: Car has no field named 'action_checkbox'

During handling of the above exception, another exception occurred:

Traceback (most recent call last):
  File "/usr/local/lib/python3.12/site-packages/asgiref/sync.py", line 489, in thread_handler
    raise exc_info[1]
  File "/usr/local/lib/python3.12/site-packages/django/core/handlers/exception.py", line 42, in inner
    response = await get_response(request)
               ^^^^^^^^^^^^^^^^^^^^^^^^^^^
  File "/usr/local/lib/python3.12/site-packages/asgiref/sync.py", line 489, in thread_handler
    raise exc_info[1]
  File "/usr/local/lib/python3.12/site-packages/django/core/handlers/base.py", line 284, in _get_response_async
    response = await sync_to_async(
               ^^^^^^^^^^^^^^^^^^^^
  File "/usr/local/lib/python3.12/site-packages/asgiref/sync.py", line 439, in __call__
    ret = await asyncio.shield(exec_coro)
          ^^^^^^^^^^^^^^^^^^^^^^^^^^^^^^^
  File "/usr/local/lib/python3.12/concurrent/futures/thread.py", line 59, in run
    result = self.fn(*self.args, **self.kwargs)
             ^^^^^^^^^^^^^^^^^^^^^^^^^^^^^^^^^^
  File "/usr/local/lib/python3.12/site-packages/asgiref/sync.py", line 493, in thread_handler
    return func(*args, **kwargs)
           ^^^^^^^^^^^^^^^^^^^^^
  File "/usr/local/lib/python3.12/site-packages/django/template/response.py", line 114, in render
    self.content = self.rendered_content
                   ^^^^^^^^^^^^^^^^^^^^^
  File "/usr/local/lib/python3.12/site-packages/django/template/response.py", line 92, in rendered_content
    return template.render(context, self._request)
           ^^^^^^^^^^^^^^^^^^^^^^^^^^^^^^^^^^^^^^^
  File "/usr/local/lib/python3.12/site-packages/django/template/backends/django.py", line 107, in render
    return self.template.render(context)
           ^^^^^^^^^^^^^^^^^^^^^^^^^^^^^
  File "/usr/local/lib/python3.12/site-packages/django/template/base.py", line 171, in render
    return self._render(context)
           ^^^^^^^^^^^^^^^^^^^^^
  File "/usr/local/lib/python3.12/site-packages/django/template/base.py", line 163, in _render
    return self.nodelist.render(context)
           ^^^^^^^^^^^^^^^^^^^^^^^^^^^^^
  File "/usr/local/lib/python3.12/site-packages/django/template/base.py", line 1016, in render
    return SafeString("".join([node.render_annotated(context) for node in self]))
                               ^^^^^^^^^^^^^^^^^^^^^^^^^^^^^^
  File "/usr/local/lib/python3.12/site-packages/django/template/base.py", line 977, in render_annotated
    return self.render(context)
           ^^^^^^^^^^^^^^^^^^^^
  File "/usr/local/lib/python3.12/site-packages/django/template/loader_tags.py", line 159, in render
    return compiled_parent._render(context)
           ^^^^^^^^^^^^^^^^^^^^^^^^^^^^^^^^
  File "/usr/local/lib/python3.12/site-packages/django/template/base.py", line 163, in _render
    return self.nodelist.render(context)
           ^^^^^^^^^^^^^^^^^^^^^^^^^^^^^
  File "/usr/local/lib/python3.12/site-packages/django/template/base.py", line 1016, in render
    return SafeString("".join([node.render_annotated(context) for node in self]))
                               ^^^^^^^^^^^^^^^^^^^^^^^^^^^^^^
  File "/usr/local/lib/python3.12/site-packages/django/template/base.py", line 977, in render_annotated
    return self.render(context)
           ^^^^^^^^^^^^^^^^^^^^
  File "/usr/local/lib/python3.12/site-packages/django/template/loader_tags.py", line 159, in render
    return compiled_parent._render(context)
           ^^^^^^^^^^^^^^^^^^^^^^^^^^^^^^^^
  File "/usr/local/lib/python3.12/site-packages/django/template/base.py", line 163, in _render
    return self.nodelist.render(context)
           ^^^^^^^^^^^^^^^^^^^^^^^^^^^^^
  File "/usr/local/lib/python3.12/site-packages/django/template/base.py", line 1016, in render
    return SafeString("".join([node.render_annotated(context) for node in self]))
                               ^^^^^^^^^^^^^^^^^^^^^^^^^^^^^^
  File "/usr/local/lib/python3.12/site-packages/django/template/base.py", line 977, in render_annotated
    return self.render(context)
           ^^^^^^^^^^^^^^^^^^^^
  File "/usr/local/lib/python3.12/site-packages/django/template/loader_tags.py", line 65, in render
    result = block.nodelist.render(context)
             ^^^^^^^^^^^^^^^^^^^^^^^^^^^^^^
  File "/usr/local/lib/python3.12/site-packages/django/template/base.py", line 1016, in render
    return SafeString("".join([node.render_annotated(context) for node in self]))
                               ^^^^^^^^^^^^^^^^^^^^^^^^^^^^^^
  File "/usr/local/lib/python3.12/site-packages/django/template/base.py", line 977, in render_annotated
    return self.render(context)
           ^^^^^^^^^^^^^^^^^^^^
  File "/usr/local/lib/python3.12/site-packages/django/template/loader_tags.py", line 65, in render
    result = block.nodelist.render(context)
             ^^^^^^^^^^^^^^^^^^^^^^^^^^^^^^
  File "/usr/local/lib/python3.12/site-packages/django/template/base.py", line 1016, in render
    return SafeString("".join([node.render_annotated(context) for node in self]))
                               ^^^^^^^^^^^^^^^^^^^^^^^^^^^^^^
  File "/usr/local/lib/python3.12/site-packages/django/template/base.py", line 977, in render_annotated
    return self.render(context)
           ^^^^^^^^^^^^^^^^^^^^
  File "/usr/local/lib/python3.12/site-packages/django/template/loader_tags.py", line 65, in render
    result = block.nodelist.render(context)
             ^^^^^^^^^^^^^^^^^^^^^^^^^^^^^^
  File "/usr/local/lib/python3.12/site-packages/django/template/base.py", line 1016, in render
    return SafeString("".join([node.render_annotated(context) for node in self]))
                               ^^^^^^^^^^^^^^^^^^^^^^^^^^^^^^
  File "/usr/local/lib/python3.12/site-packages/django/template/base.py", line 977, in render_annotated
    return self.render(context)
           ^^^^^^^^^^^^^^^^^^^^
  File "/usr/local/lib/python3.12/site-packages/django/contrib/admin/templatetags/base.py", line 45, in render
    return super().render(context)
           ^^^^^^^^^^^^^^^^^^^^^^^
  File "/usr/local/lib/python3.12/site-packages/django/template/library.py", line 359, in render
    _dict = self.func(*resolved_args, **resolved_kwargs)
            ^^^^^^^^^^^^^^^^^^^^^^^^^^^^^^^^^^^^^^^^^^^^
  File "/usr/local/lib/python3.12/site-packages/django/contrib/admin/templatetags/admin_list.py", line 354, in result_list
    "results": list(results(cl)),
               ^^^^^^^^^^^^^^^^^
  File "/usr/local/lib/python3.12/site-packages/django/contrib/admin/templatetags/admin_list.py", line 330, in results
    yield ResultList(None, items_for_result(cl, res, None))
          ^^^^^^^^^^^^^^^^^^^^^^^^^^^^^^^^^^^^^^^^^^^^^^^^^
  File "/usr/local/lib/python3.12/site-packages/django/contrib/admin/templatetags/admin_list.py", line 321, in __init__
    super().__init__(*items)
  File "/usr/local/lib/python3.12/site-packages/django/contrib/admin/templatetags/admin_list.py", line 219, in items_for_result
    f, attr, value = lookup_field(field_name, result, cl.model_admin)
                     ^^^^^^^^^^^^^^^^^^^^^^^^^^^^^^^^^^^^^^^^^^^^^^^^
  File "/usr/local/lib/python3.12/site-packages/django/contrib/admin/utils.py", line 299, in lookup_field
    value = attr(obj)
            ^^^^^^^^^
  File "/usr/local/lib/python3.12/site-packages/django/contrib/admin/options.py", line 1031, in action_checkbox
    _("Select this object for an action - {}"), str(obj)
                                                ^^^^^^^^
  File "/code/core/apps/cars/models/car.py", line 24, in __str__
    return f'car {self.date}, price {self.price}rubl'
                  ^^^^^^^^^
AttributeError: 'Car' object has no attribute 'date'
ERROR 2025-08-02 15:12:54,361 log Internal Server Error: /admin/cars/car/
Traceback (most recent call last):
  File "/usr/local/lib/python3.12/site-packages/django/db/models/options.py", line 683, in get_field
    return self.fields_map[field_name]
           ~~~~~~~~~~~~~~~^^^^^^^^^^^^
KeyError: 'action_checkbox'

During handling of the above exception, another exception occurred:

Traceback (most recent call last):
  File "/usr/local/lib/python3.12/site-packages/django/contrib/admin/utils.py", line 290, in lookup_field
    f = _get_non_gfk_field(opts, name)
        ^^^^^^^^^^^^^^^^^^^^^^^^^^^^^^
  File "/usr/local/lib/python3.12/site-packages/django/contrib/admin/utils.py", line 330, in _get_non_gfk_field
    field = opts.get_field(name)
            ^^^^^^^^^^^^^^^^^^^^
  File "/usr/local/lib/python3.12/site-packages/django/db/models/options.py", line 685, in get_field
    raise FieldDoesNotExist(
django.core.exceptions.FieldDoesNotExist: Car has no field named 'action_checkbox'

During handling of the above exception, another exception occurred:

Traceback (most recent call last):
  File "/usr/local/lib/python3.12/site-packages/asgiref/sync.py", line 489, in thread_handler
    raise exc_info[1]
  File "/usr/local/lib/python3.12/site-packages/django/core/handlers/exception.py", line 42, in inner
    response = await get_response(request)
               ^^^^^^^^^^^^^^^^^^^^^^^^^^^
  File "/usr/local/lib/python3.12/site-packages/asgiref/sync.py", line 489, in thread_handler
    raise exc_info[1]
  File "/usr/local/lib/python3.12/site-packages/django/core/handlers/base.py", line 284, in _get_response_async
    response = await sync_to_async(
               ^^^^^^^^^^^^^^^^^^^^
  File "/usr/local/lib/python3.12/site-packages/asgiref/sync.py", line 439, in __call__
    ret = await asyncio.shield(exec_coro)
          ^^^^^^^^^^^^^^^^^^^^^^^^^^^^^^^
  File "/usr/local/lib/python3.12/concurrent/futures/thread.py", line 59, in run
    result = self.fn(*self.args, **self.kwargs)
             ^^^^^^^^^^^^^^^^^^^^^^^^^^^^^^^^^^
  File "/usr/local/lib/python3.12/site-packages/asgiref/sync.py", line 493, in thread_handler
    return func(*args, **kwargs)
           ^^^^^^^^^^^^^^^^^^^^^
  File "/usr/local/lib/python3.12/site-packages/django/template/response.py", line 114, in render
    self.content = self.rendered_content
                   ^^^^^^^^^^^^^^^^^^^^^
  File "/usr/local/lib/python3.12/site-packages/django/template/response.py", line 92, in rendered_content
    return template.render(context, self._request)
           ^^^^^^^^^^^^^^^^^^^^^^^^^^^^^^^^^^^^^^^
  File "/usr/local/lib/python3.12/site-packages/django/template/backends/django.py", line 107, in render
    return self.template.render(context)
           ^^^^^^^^^^^^^^^^^^^^^^^^^^^^^
  File "/usr/local/lib/python3.12/site-packages/django/template/base.py", line 171, in render
    return self._render(context)
           ^^^^^^^^^^^^^^^^^^^^^
  File "/usr/local/lib/python3.12/site-packages/django/template/base.py", line 163, in _render
    return self.nodelist.render(context)
           ^^^^^^^^^^^^^^^^^^^^^^^^^^^^^
  File "/usr/local/lib/python3.12/site-packages/django/template/base.py", line 1016, in render
    return SafeString("".join([node.render_annotated(context) for node in self]))
                               ^^^^^^^^^^^^^^^^^^^^^^^^^^^^^^
  File "/usr/local/lib/python3.12/site-packages/django/template/base.py", line 977, in render_annotated
    return self.render(context)
           ^^^^^^^^^^^^^^^^^^^^
  File "/usr/local/lib/python3.12/site-packages/django/template/loader_tags.py", line 159, in render
    return compiled_parent._render(context)
           ^^^^^^^^^^^^^^^^^^^^^^^^^^^^^^^^
  File "/usr/local/lib/python3.12/site-packages/django/template/base.py", line 163, in _render
    return self.nodelist.render(context)
           ^^^^^^^^^^^^^^^^^^^^^^^^^^^^^
  File "/usr/local/lib/python3.12/site-packages/django/template/base.py", line 1016, in render
    return SafeString("".join([node.render_annotated(context) for node in self]))
                               ^^^^^^^^^^^^^^^^^^^^^^^^^^^^^^
  File "/usr/local/lib/python3.12/site-packages/django/template/base.py", line 977, in render_annotated
    return self.render(context)
           ^^^^^^^^^^^^^^^^^^^^
  File "/usr/local/lib/python3.12/site-packages/django/template/loader_tags.py", line 159, in render
    return compiled_parent._render(context)
           ^^^^^^^^^^^^^^^^^^^^^^^^^^^^^^^^
  File "/usr/local/lib/python3.12/site-packages/django/template/base.py", line 163, in _render
    return self.nodelist.render(context)
           ^^^^^^^^^^^^^^^^^^^^^^^^^^^^^
  File "/usr/local/lib/python3.12/site-packages/django/template/base.py", line 1016, in render
    return SafeString("".join([node.render_annotated(context) for node in self]))
                               ^^^^^^^^^^^^^^^^^^^^^^^^^^^^^^
  File "/usr/local/lib/python3.12/site-packages/django/template/base.py", line 977, in render_annotated
    return self.render(context)
           ^^^^^^^^^^^^^^^^^^^^
  File "/usr/local/lib/python3.12/site-packages/django/template/loader_tags.py", line 65, in render
    result = block.nodelist.render(context)
             ^^^^^^^^^^^^^^^^^^^^^^^^^^^^^^
  File "/usr/local/lib/python3.12/site-packages/django/template/base.py", line 1016, in render
    return SafeString("".join([node.render_annotated(context) for node in self]))
                               ^^^^^^^^^^^^^^^^^^^^^^^^^^^^^^
  File "/usr/local/lib/python3.12/site-packages/django/template/base.py", line 977, in render_annotated
    return self.render(context)
           ^^^^^^^^^^^^^^^^^^^^
  File "/usr/local/lib/python3.12/site-packages/django/template/loader_tags.py", line 65, in render
    result = block.nodelist.render(context)
             ^^^^^^^^^^^^^^^^^^^^^^^^^^^^^^
  File "/usr/local/lib/python3.12/site-packages/django/template/base.py", line 1016, in render
    return SafeString("".join([node.render_annotated(context) for node in self]))
                               ^^^^^^^^^^^^^^^^^^^^^^^^^^^^^^
  File "/usr/local/lib/python3.12/site-packages/django/template/base.py", line 977, in render_annotated
    return self.render(context)
           ^^^^^^^^^^^^^^^^^^^^
  File "/usr/local/lib/python3.12/site-packages/django/template/loader_tags.py", line 65, in render
    result = block.nodelist.render(context)
             ^^^^^^^^^^^^^^^^^^^^^^^^^^^^^^
  File "/usr/local/lib/python3.12/site-packages/django/template/base.py", line 1016, in render
    return SafeString("".join([node.render_annotated(context) for node in self]))
                               ^^^^^^^^^^^^^^^^^^^^^^^^^^^^^^
  File "/usr/local/lib/python3.12/site-packages/django/template/base.py", line 977, in render_annotated
    return self.render(context)
           ^^^^^^^^^^^^^^^^^^^^
  File "/usr/local/lib/python3.12/site-packages/django/contrib/admin/templatetags/base.py", line 45, in render
    return super().render(context)
           ^^^^^^^^^^^^^^^^^^^^^^^
  File "/usr/local/lib/python3.12/site-packages/django/template/library.py", line 359, in render
    _dict = self.func(*resolved_args, **resolved_kwargs)
            ^^^^^^^^^^^^^^^^^^^^^^^^^^^^^^^^^^^^^^^^^^^^
  File "/usr/local/lib/python3.12/site-packages/django/contrib/admin/templatetags/admin_list.py", line 354, in result_list
    "results": list(results(cl)),
               ^^^^^^^^^^^^^^^^^
  File "/usr/local/lib/python3.12/site-packages/django/contrib/admin/templatetags/admin_list.py", line 330, in results
    yield ResultList(None, items_for_result(cl, res, None))
          ^^^^^^^^^^^^^^^^^^^^^^^^^^^^^^^^^^^^^^^^^^^^^^^^^
  File "/usr/local/lib/python3.12/site-packages/django/contrib/admin/templatetags/admin_list.py", line 321, in __init__
    super().__init__(*items)
  File "/usr/local/lib/python3.12/site-packages/django/contrib/admin/templatetags/admin_list.py", line 219, in items_for_result
    f, attr, value = lookup_field(field_name, result, cl.model_admin)
                     ^^^^^^^^^^^^^^^^^^^^^^^^^^^^^^^^^^^^^^^^^^^^^^^^
  File "/usr/local/lib/python3.12/site-packages/django/contrib/admin/utils.py", line 299, in lookup_field
    value = attr(obj)
            ^^^^^^^^^
  File "/usr/local/lib/python3.12/site-packages/django/contrib/admin/options.py", line 1031, in action_checkbox
    _("Select this object for an action - {}"), str(obj)
                                                ^^^^^^^^
  File "/code/core/apps/cars/models/car.py", line 24, in __str__
    return f'car {self.date}, price {self.price}rubl'
                  ^^^^^^^^^
AttributeError: 'Car' object has no attribute 'date'
ERROR 2025-08-02 15:12:55,882 log Internal Server Error: /admin/cars/car/
Traceback (most recent call last):
  File "/usr/local/lib/python3.12/site-packages/django/db/models/options.py", line 683, in get_field
    return self.fields_map[field_name]
           ~~~~~~~~~~~~~~~^^^^^^^^^^^^
KeyError: 'action_checkbox'

During handling of the above exception, another exception occurred:

Traceback (most recent call last):
  File "/usr/local/lib/python3.12/site-packages/django/contrib/admin/utils.py", line 290, in lookup_field
    f = _get_non_gfk_field(opts, name)
        ^^^^^^^^^^^^^^^^^^^^^^^^^^^^^^
  File "/usr/local/lib/python3.12/site-packages/django/contrib/admin/utils.py", line 330, in _get_non_gfk_field
    field = opts.get_field(name)
            ^^^^^^^^^^^^^^^^^^^^
  File "/usr/local/lib/python3.12/site-packages/django/db/models/options.py", line 685, in get_field
    raise FieldDoesNotExist(
django.core.exceptions.FieldDoesNotExist: Car has no field named 'action_checkbox'

During handling of the above exception, another exception occurred:

Traceback (most recent call last):
  File "/usr/local/lib/python3.12/site-packages/asgiref/sync.py", line 489, in thread_handler
    raise exc_info[1]
  File "/usr/local/lib/python3.12/site-packages/django/core/handlers/exception.py", line 42, in inner
    response = await get_response(request)
               ^^^^^^^^^^^^^^^^^^^^^^^^^^^
  File "/usr/local/lib/python3.12/site-packages/asgiref/sync.py", line 489, in thread_handler
    raise exc_info[1]
  File "/usr/local/lib/python3.12/site-packages/django/core/handlers/base.py", line 284, in _get_response_async
    response = await sync_to_async(
               ^^^^^^^^^^^^^^^^^^^^
  File "/usr/local/lib/python3.12/site-packages/asgiref/sync.py", line 439, in __call__
    ret = await asyncio.shield(exec_coro)
          ^^^^^^^^^^^^^^^^^^^^^^^^^^^^^^^
  File "/usr/local/lib/python3.12/concurrent/futures/thread.py", line 59, in run
    result = self.fn(*self.args, **self.kwargs)
             ^^^^^^^^^^^^^^^^^^^^^^^^^^^^^^^^^^
  File "/usr/local/lib/python3.12/site-packages/asgiref/sync.py", line 493, in thread_handler
    return func(*args, **kwargs)
           ^^^^^^^^^^^^^^^^^^^^^
  File "/usr/local/lib/python3.12/site-packages/django/template/response.py", line 114, in render
    self.content = self.rendered_content
                   ^^^^^^^^^^^^^^^^^^^^^
  File "/usr/local/lib/python3.12/site-packages/django/template/response.py", line 92, in rendered_content
    return template.render(context, self._request)
           ^^^^^^^^^^^^^^^^^^^^^^^^^^^^^^^^^^^^^^^
  File "/usr/local/lib/python3.12/site-packages/django/template/backends/django.py", line 107, in render
    return self.template.render(context)
           ^^^^^^^^^^^^^^^^^^^^^^^^^^^^^
  File "/usr/local/lib/python3.12/site-packages/django/template/base.py", line 171, in render
    return self._render(context)
           ^^^^^^^^^^^^^^^^^^^^^
  File "/usr/local/lib/python3.12/site-packages/django/template/base.py", line 163, in _render
    return self.nodelist.render(context)
           ^^^^^^^^^^^^^^^^^^^^^^^^^^^^^
  File "/usr/local/lib/python3.12/site-packages/django/template/base.py", line 1016, in render
    return SafeString("".join([node.render_annotated(context) for node in self]))
                               ^^^^^^^^^^^^^^^^^^^^^^^^^^^^^^
  File "/usr/local/lib/python3.12/site-packages/django/template/base.py", line 977, in render_annotated
    return self.render(context)
           ^^^^^^^^^^^^^^^^^^^^
  File "/usr/local/lib/python3.12/site-packages/django/template/loader_tags.py", line 159, in render
    return compiled_parent._render(context)
           ^^^^^^^^^^^^^^^^^^^^^^^^^^^^^^^^
  File "/usr/local/lib/python3.12/site-packages/django/template/base.py", line 163, in _render
    return self.nodelist.render(context)
           ^^^^^^^^^^^^^^^^^^^^^^^^^^^^^
  File "/usr/local/lib/python3.12/site-packages/django/template/base.py", line 1016, in render
    return SafeString("".join([node.render_annotated(context) for node in self]))
                               ^^^^^^^^^^^^^^^^^^^^^^^^^^^^^^
  File "/usr/local/lib/python3.12/site-packages/django/template/base.py", line 977, in render_annotated
    return self.render(context)
           ^^^^^^^^^^^^^^^^^^^^
  File "/usr/local/lib/python3.12/site-packages/django/template/loader_tags.py", line 159, in render
    return compiled_parent._render(context)
           ^^^^^^^^^^^^^^^^^^^^^^^^^^^^^^^^
  File "/usr/local/lib/python3.12/site-packages/django/template/base.py", line 163, in _render
    return self.nodelist.render(context)
           ^^^^^^^^^^^^^^^^^^^^^^^^^^^^^
  File "/usr/local/lib/python3.12/site-packages/django/template/base.py", line 1016, in render
    return SafeString("".join([node.render_annotated(context) for node in self]))
                               ^^^^^^^^^^^^^^^^^^^^^^^^^^^^^^
  File "/usr/local/lib/python3.12/site-packages/django/template/base.py", line 977, in render_annotated
    return self.render(context)
           ^^^^^^^^^^^^^^^^^^^^
  File "/usr/local/lib/python3.12/site-packages/django/template/loader_tags.py", line 65, in render
    result = block.nodelist.render(context)
             ^^^^^^^^^^^^^^^^^^^^^^^^^^^^^^
  File "/usr/local/lib/python3.12/site-packages/django/template/base.py", line 1016, in render
    return SafeString("".join([node.render_annotated(context) for node in self]))
                               ^^^^^^^^^^^^^^^^^^^^^^^^^^^^^^
  File "/usr/local/lib/python3.12/site-packages/django/template/base.py", line 977, in render_annotated
    return self.render(context)
           ^^^^^^^^^^^^^^^^^^^^
  File "/usr/local/lib/python3.12/site-packages/django/template/loader_tags.py", line 65, in render
    result = block.nodelist.render(context)
             ^^^^^^^^^^^^^^^^^^^^^^^^^^^^^^
  File "/usr/local/lib/python3.12/site-packages/django/template/base.py", line 1016, in render
    return SafeString("".join([node.render_annotated(context) for node in self]))
                               ^^^^^^^^^^^^^^^^^^^^^^^^^^^^^^
  File "/usr/local/lib/python3.12/site-packages/django/template/base.py", line 977, in render_annotated
    return self.render(context)
           ^^^^^^^^^^^^^^^^^^^^
  File "/usr/local/lib/python3.12/site-packages/django/template/loader_tags.py", line 65, in render
    result = block.nodelist.render(context)
             ^^^^^^^^^^^^^^^^^^^^^^^^^^^^^^
  File "/usr/local/lib/python3.12/site-packages/django/template/base.py", line 1016, in render
    return SafeString("".join([node.render_annotated(context) for node in self]))
                               ^^^^^^^^^^^^^^^^^^^^^^^^^^^^^^
  File "/usr/local/lib/python3.12/site-packages/django/template/base.py", line 977, in render_annotated
    return self.render(context)
           ^^^^^^^^^^^^^^^^^^^^
  File "/usr/local/lib/python3.12/site-packages/django/contrib/admin/templatetags/base.py", line 45, in render
    return super().render(context)
           ^^^^^^^^^^^^^^^^^^^^^^^
  File "/usr/local/lib/python3.12/site-packages/django/template/library.py", line 359, in render
    _dict = self.func(*resolved_args, **resolved_kwargs)
            ^^^^^^^^^^^^^^^^^^^^^^^^^^^^^^^^^^^^^^^^^^^^
  File "/usr/local/lib/python3.12/site-packages/django/contrib/admin/templatetags/admin_list.py", line 354, in result_list
    "results": list(results(cl)),
               ^^^^^^^^^^^^^^^^^
  File "/usr/local/lib/python3.12/site-packages/django/contrib/admin/templatetags/admin_list.py", line 330, in results
    yield ResultList(None, items_for_result(cl, res, None))
          ^^^^^^^^^^^^^^^^^^^^^^^^^^^^^^^^^^^^^^^^^^^^^^^^^
  File "/usr/local/lib/python3.12/site-packages/django/contrib/admin/templatetags/admin_list.py", line 321, in __init__
    super().__init__(*items)
  File "/usr/local/lib/python3.12/site-packages/django/contrib/admin/templatetags/admin_list.py", line 219, in items_for_result
    f, attr, value = lookup_field(field_name, result, cl.model_admin)
                     ^^^^^^^^^^^^^^^^^^^^^^^^^^^^^^^^^^^^^^^^^^^^^^^^
  File "/usr/local/lib/python3.12/site-packages/django/contrib/admin/utils.py", line 299, in lookup_field
    value = attr(obj)
            ^^^^^^^^^
  File "/usr/local/lib/python3.12/site-packages/django/contrib/admin/options.py", line 1031, in action_checkbox
    _("Select this object for an action - {}"), str(obj)
                                                ^^^^^^^^
  File "/code/core/apps/cars/models/car.py", line 24, in __str__
    return f'car {self.date}, price {self.price}rubl'
                  ^^^^^^^^^
AttributeError: 'Car' object has no attribute 'date'
ERROR 2025-08-02 15:12:58,078 log Internal Server Error: /admin/cars/car/
Traceback (most recent call last):
  File "/usr/local/lib/python3.12/site-packages/django/db/models/options.py", line 683, in get_field
    return self.fields_map[field_name]
           ~~~~~~~~~~~~~~~^^^^^^^^^^^^
KeyError: 'action_checkbox'

During handling of the above exception, another exception occurred:

Traceback (most recent call last):
  File "/usr/local/lib/python3.12/site-packages/django/contrib/admin/utils.py", line 290, in lookup_field
    f = _get_non_gfk_field(opts, name)
        ^^^^^^^^^^^^^^^^^^^^^^^^^^^^^^
  File "/usr/local/lib/python3.12/site-packages/django/contrib/admin/utils.py", line 330, in _get_non_gfk_field
    field = opts.get_field(name)
            ^^^^^^^^^^^^^^^^^^^^
  File "/usr/local/lib/python3.12/site-packages/django/db/models/options.py", line 685, in get_field
    raise FieldDoesNotExist(
django.core.exceptions.FieldDoesNotExist: Car has no field named 'action_checkbox'

During handling of the above exception, another exception occurred:

Traceback (most recent call last):
  File "/usr/local/lib/python3.12/site-packages/asgiref/sync.py", line 489, in thread_handler
    raise exc_info[1]
  File "/usr/local/lib/python3.12/site-packages/django/core/handlers/exception.py", line 42, in inner
    response = await get_response(request)
               ^^^^^^^^^^^^^^^^^^^^^^^^^^^
  File "/usr/local/lib/python3.12/site-packages/asgiref/sync.py", line 489, in thread_handler
    raise exc_info[1]
  File "/usr/local/lib/python3.12/site-packages/django/core/handlers/base.py", line 284, in _get_response_async
    response = await sync_to_async(
               ^^^^^^^^^^^^^^^^^^^^
  File "/usr/local/lib/python3.12/site-packages/asgiref/sync.py", line 439, in __call__
    ret = await asyncio.shield(exec_coro)
          ^^^^^^^^^^^^^^^^^^^^^^^^^^^^^^^
  File "/usr/local/lib/python3.12/concurrent/futures/thread.py", line 59, in run
    result = self.fn(*self.args, **self.kwargs)
             ^^^^^^^^^^^^^^^^^^^^^^^^^^^^^^^^^^
  File "/usr/local/lib/python3.12/site-packages/asgiref/sync.py", line 493, in thread_handler
    return func(*args, **kwargs)
           ^^^^^^^^^^^^^^^^^^^^^
  File "/usr/local/lib/python3.12/site-packages/django/template/response.py", line 114, in render
    self.content = self.rendered_content
                   ^^^^^^^^^^^^^^^^^^^^^
  File "/usr/local/lib/python3.12/site-packages/django/template/response.py", line 92, in rendered_content
    return template.render(context, self._request)
           ^^^^^^^^^^^^^^^^^^^^^^^^^^^^^^^^^^^^^^^
  File "/usr/local/lib/python3.12/site-packages/django/template/backends/django.py", line 107, in render
    return self.template.render(context)
           ^^^^^^^^^^^^^^^^^^^^^^^^^^^^^
  File "/usr/local/lib/python3.12/site-packages/django/template/base.py", line 171, in render
    return self._render(context)
           ^^^^^^^^^^^^^^^^^^^^^
  File "/usr/local/lib/python3.12/site-packages/django/template/base.py", line 163, in _render
    return self.nodelist.render(context)
           ^^^^^^^^^^^^^^^^^^^^^^^^^^^^^
  File "/usr/local/lib/python3.12/site-packages/django/template/base.py", line 1016, in render
    return SafeString("".join([node.render_annotated(context) for node in self]))
                               ^^^^^^^^^^^^^^^^^^^^^^^^^^^^^^
  File "/usr/local/lib/python3.12/site-packages/django/template/base.py", line 977, in render_annotated
    return self.render(context)
           ^^^^^^^^^^^^^^^^^^^^
  File "/usr/local/lib/python3.12/site-packages/django/template/loader_tags.py", line 159, in render
    return compiled_parent._render(context)
           ^^^^^^^^^^^^^^^^^^^^^^^^^^^^^^^^
  File "/usr/local/lib/python3.12/site-packages/django/template/base.py", line 163, in _render
    return self.nodelist.render(context)
           ^^^^^^^^^^^^^^^^^^^^^^^^^^^^^
  File "/usr/local/lib/python3.12/site-packages/django/template/base.py", line 1016, in render
    return SafeString("".join([node.render_annotated(context) for node in self]))
                               ^^^^^^^^^^^^^^^^^^^^^^^^^^^^^^
  File "/usr/local/lib/python3.12/site-packages/django/template/base.py", line 977, in render_annotated
    return self.render(context)
           ^^^^^^^^^^^^^^^^^^^^
  File "/usr/local/lib/python3.12/site-packages/django/template/loader_tags.py", line 159, in render
    return compiled_parent._render(context)
           ^^^^^^^^^^^^^^^^^^^^^^^^^^^^^^^^
  File "/usr/local/lib/python3.12/site-packages/django/template/base.py", line 163, in _render
    return self.nodelist.render(context)
           ^^^^^^^^^^^^^^^^^^^^^^^^^^^^^
  File "/usr/local/lib/python3.12/site-packages/django/template/base.py", line 1016, in render
    return SafeString("".join([node.render_annotated(context) for node in self]))
                               ^^^^^^^^^^^^^^^^^^^^^^^^^^^^^^
  File "/usr/local/lib/python3.12/site-packages/django/template/base.py", line 977, in render_annotated
    return self.render(context)
           ^^^^^^^^^^^^^^^^^^^^
  File "/usr/local/lib/python3.12/site-packages/django/template/loader_tags.py", line 65, in render
    result = block.nodelist.render(context)
             ^^^^^^^^^^^^^^^^^^^^^^^^^^^^^^
  File "/usr/local/lib/python3.12/site-packages/django/template/base.py", line 1016, in render
    return SafeString("".join([node.render_annotated(context) for node in self]))
                               ^^^^^^^^^^^^^^^^^^^^^^^^^^^^^^
  File "/usr/local/lib/python3.12/site-packages/django/template/base.py", line 977, in render_annotated
    return self.render(context)
           ^^^^^^^^^^^^^^^^^^^^
  File "/usr/local/lib/python3.12/site-packages/django/template/loader_tags.py", line 65, in render
    result = block.nodelist.render(context)
             ^^^^^^^^^^^^^^^^^^^^^^^^^^^^^^
  File "/usr/local/lib/python3.12/site-packages/django/template/base.py", line 1016, in render
    return SafeString("".join([node.render_annotated(context) for node in self]))
                               ^^^^^^^^^^^^^^^^^^^^^^^^^^^^^^
  File "/usr/local/lib/python3.12/site-packages/django/template/base.py", line 977, in render_annotated
    return self.render(context)
           ^^^^^^^^^^^^^^^^^^^^
  File "/usr/local/lib/python3.12/site-packages/django/template/loader_tags.py", line 65, in render
    result = block.nodelist.render(context)
             ^^^^^^^^^^^^^^^^^^^^^^^^^^^^^^
  File "/usr/local/lib/python3.12/site-packages/django/template/base.py", line 1016, in render
    return SafeString("".join([node.render_annotated(context) for node in self]))
                               ^^^^^^^^^^^^^^^^^^^^^^^^^^^^^^
  File "/usr/local/lib/python3.12/site-packages/django/template/base.py", line 977, in render_annotated
    return self.render(context)
           ^^^^^^^^^^^^^^^^^^^^
  File "/usr/local/lib/python3.12/site-packages/django/contrib/admin/templatetags/base.py", line 45, in render
    return super().render(context)
           ^^^^^^^^^^^^^^^^^^^^^^^
  File "/usr/local/lib/python3.12/site-packages/django/template/library.py", line 359, in render
    _dict = self.func(*resolved_args, **resolved_kwargs)
            ^^^^^^^^^^^^^^^^^^^^^^^^^^^^^^^^^^^^^^^^^^^^
  File "/usr/local/lib/python3.12/site-packages/django/contrib/admin/templatetags/admin_list.py", line 354, in result_list
    "results": list(results(cl)),
               ^^^^^^^^^^^^^^^^^
  File "/usr/local/lib/python3.12/site-packages/django/contrib/admin/templatetags/admin_list.py", line 330, in results
    yield ResultList(None, items_for_result(cl, res, None))
          ^^^^^^^^^^^^^^^^^^^^^^^^^^^^^^^^^^^^^^^^^^^^^^^^^
  File "/usr/local/lib/python3.12/site-packages/django/contrib/admin/templatetags/admin_list.py", line 321, in __init__
    super().__init__(*items)
  File "/usr/local/lib/python3.12/site-packages/django/contrib/admin/templatetags/admin_list.py", line 219, in items_for_result
    f, attr, value = lookup_field(field_name, result, cl.model_admin)
                     ^^^^^^^^^^^^^^^^^^^^^^^^^^^^^^^^^^^^^^^^^^^^^^^^
  File "/usr/local/lib/python3.12/site-packages/django/contrib/admin/utils.py", line 299, in lookup_field
    value = attr(obj)
            ^^^^^^^^^
  File "/usr/local/lib/python3.12/site-packages/django/contrib/admin/options.py", line 1031, in action_checkbox
    _("Select this object for an action - {}"), str(obj)
                                                ^^^^^^^^
  File "/code/core/apps/cars/models/car.py", line 24, in __str__
    return f'car {self.date}, price {self.price}rubl'
                  ^^^^^^^^^
AttributeError: 'Car' object has no attribute 'date'
ERROR 2025-08-02 15:13:33,321 log Internal Server Error: /admin/cars/car/
Traceback (most recent call last):
  File "/usr/local/lib/python3.12/site-packages/django/db/models/options.py", line 683, in get_field
    return self.fields_map[field_name]
           ~~~~~~~~~~~~~~~^^^^^^^^^^^^
KeyError: 'action_checkbox'

During handling of the above exception, another exception occurred:

Traceback (most recent call last):
  File "/usr/local/lib/python3.12/site-packages/django/contrib/admin/utils.py", line 290, in lookup_field
    f = _get_non_gfk_field(opts, name)
        ^^^^^^^^^^^^^^^^^^^^^^^^^^^^^^
  File "/usr/local/lib/python3.12/site-packages/django/contrib/admin/utils.py", line 330, in _get_non_gfk_field
    field = opts.get_field(name)
            ^^^^^^^^^^^^^^^^^^^^
  File "/usr/local/lib/python3.12/site-packages/django/db/models/options.py", line 685, in get_field
    raise FieldDoesNotExist(
django.core.exceptions.FieldDoesNotExist: Car has no field named 'action_checkbox'

During handling of the above exception, another exception occurred:

Traceback (most recent call last):
  File "/usr/local/lib/python3.12/site-packages/asgiref/sync.py", line 489, in thread_handler
    raise exc_info[1]
  File "/usr/local/lib/python3.12/site-packages/django/core/handlers/exception.py", line 42, in inner
    response = await get_response(request)
               ^^^^^^^^^^^^^^^^^^^^^^^^^^^
  File "/usr/local/lib/python3.12/site-packages/asgiref/sync.py", line 489, in thread_handler
    raise exc_info[1]
  File "/usr/local/lib/python3.12/site-packages/django/core/handlers/base.py", line 284, in _get_response_async
    response = await sync_to_async(
               ^^^^^^^^^^^^^^^^^^^^
  File "/usr/local/lib/python3.12/site-packages/asgiref/sync.py", line 439, in __call__
    ret = await asyncio.shield(exec_coro)
          ^^^^^^^^^^^^^^^^^^^^^^^^^^^^^^^
  File "/usr/local/lib/python3.12/concurrent/futures/thread.py", line 59, in run
    result = self.fn(*self.args, **self.kwargs)
             ^^^^^^^^^^^^^^^^^^^^^^^^^^^^^^^^^^
  File "/usr/local/lib/python3.12/site-packages/asgiref/sync.py", line 493, in thread_handler
    return func(*args, **kwargs)
           ^^^^^^^^^^^^^^^^^^^^^
  File "/usr/local/lib/python3.12/site-packages/django/template/response.py", line 114, in render
    self.content = self.rendered_content
                   ^^^^^^^^^^^^^^^^^^^^^
  File "/usr/local/lib/python3.12/site-packages/django/template/response.py", line 92, in rendered_content
    return template.render(context, self._request)
           ^^^^^^^^^^^^^^^^^^^^^^^^^^^^^^^^^^^^^^^
  File "/usr/local/lib/python3.12/site-packages/django/template/backends/django.py", line 107, in render
    return self.template.render(context)
           ^^^^^^^^^^^^^^^^^^^^^^^^^^^^^
  File "/usr/local/lib/python3.12/site-packages/django/template/base.py", line 171, in render
    return self._render(context)
           ^^^^^^^^^^^^^^^^^^^^^
  File "/usr/local/lib/python3.12/site-packages/django/template/base.py", line 163, in _render
    return self.nodelist.render(context)
           ^^^^^^^^^^^^^^^^^^^^^^^^^^^^^
  File "/usr/local/lib/python3.12/site-packages/django/template/base.py", line 1016, in render
    return SafeString("".join([node.render_annotated(context) for node in self]))
                               ^^^^^^^^^^^^^^^^^^^^^^^^^^^^^^
  File "/usr/local/lib/python3.12/site-packages/django/template/base.py", line 977, in render_annotated
    return self.render(context)
           ^^^^^^^^^^^^^^^^^^^^
  File "/usr/local/lib/python3.12/site-packages/django/template/loader_tags.py", line 159, in render
    return compiled_parent._render(context)
           ^^^^^^^^^^^^^^^^^^^^^^^^^^^^^^^^
  File "/usr/local/lib/python3.12/site-packages/django/template/base.py", line 163, in _render
    return self.nodelist.render(context)
           ^^^^^^^^^^^^^^^^^^^^^^^^^^^^^
  File "/usr/local/lib/python3.12/site-packages/django/template/base.py", line 1016, in render
    return SafeString("".join([node.render_annotated(context) for node in self]))
                               ^^^^^^^^^^^^^^^^^^^^^^^^^^^^^^
  File "/usr/local/lib/python3.12/site-packages/django/template/base.py", line 977, in render_annotated
    return self.render(context)
           ^^^^^^^^^^^^^^^^^^^^
  File "/usr/local/lib/python3.12/site-packages/django/template/loader_tags.py", line 159, in render
    return compiled_parent._render(context)
           ^^^^^^^^^^^^^^^^^^^^^^^^^^^^^^^^
  File "/usr/local/lib/python3.12/site-packages/django/template/base.py", line 163, in _render
    return self.nodelist.render(context)
           ^^^^^^^^^^^^^^^^^^^^^^^^^^^^^
  File "/usr/local/lib/python3.12/site-packages/django/template/base.py", line 1016, in render
    return SafeString("".join([node.render_annotated(context) for node in self]))
                               ^^^^^^^^^^^^^^^^^^^^^^^^^^^^^^
  File "/usr/local/lib/python3.12/site-packages/django/template/base.py", line 977, in render_annotated
    return self.render(context)
           ^^^^^^^^^^^^^^^^^^^^
  File "/usr/local/lib/python3.12/site-packages/django/template/loader_tags.py", line 65, in render
    result = block.nodelist.render(context)
             ^^^^^^^^^^^^^^^^^^^^^^^^^^^^^^
  File "/usr/local/lib/python3.12/site-packages/django/template/base.py", line 1016, in render
    return SafeString("".join([node.render_annotated(context) for node in self]))
                               ^^^^^^^^^^^^^^^^^^^^^^^^^^^^^^
  File "/usr/local/lib/python3.12/site-packages/django/template/base.py", line 977, in render_annotated
    return self.render(context)
           ^^^^^^^^^^^^^^^^^^^^
  File "/usr/local/lib/python3.12/site-packages/django/template/loader_tags.py", line 65, in render
    result = block.nodelist.render(context)
             ^^^^^^^^^^^^^^^^^^^^^^^^^^^^^^
  File "/usr/local/lib/python3.12/site-packages/django/template/base.py", line 1016, in render
    return SafeString("".join([node.render_annotated(context) for node in self]))
                               ^^^^^^^^^^^^^^^^^^^^^^^^^^^^^^
  File "/usr/local/lib/python3.12/site-packages/django/template/base.py", line 977, in render_annotated
    return self.render(context)
           ^^^^^^^^^^^^^^^^^^^^
  File "/usr/local/lib/python3.12/site-packages/django/template/loader_tags.py", line 65, in render
    result = block.nodelist.render(context)
             ^^^^^^^^^^^^^^^^^^^^^^^^^^^^^^
  File "/usr/local/lib/python3.12/site-packages/django/template/base.py", line 1016, in render
    return SafeString("".join([node.render_annotated(context) for node in self]))
                               ^^^^^^^^^^^^^^^^^^^^^^^^^^^^^^
  File "/usr/local/lib/python3.12/site-packages/django/template/base.py", line 977, in render_annotated
    return self.render(context)
           ^^^^^^^^^^^^^^^^^^^^
  File "/usr/local/lib/python3.12/site-packages/django/contrib/admin/templatetags/base.py", line 45, in render
    return super().render(context)
           ^^^^^^^^^^^^^^^^^^^^^^^
  File "/usr/local/lib/python3.12/site-packages/django/template/library.py", line 359, in render
    _dict = self.func(*resolved_args, **resolved_kwargs)
            ^^^^^^^^^^^^^^^^^^^^^^^^^^^^^^^^^^^^^^^^^^^^
  File "/usr/local/lib/python3.12/site-packages/django/contrib/admin/templatetags/admin_list.py", line 354, in result_list
    "results": list(results(cl)),
               ^^^^^^^^^^^^^^^^^
  File "/usr/local/lib/python3.12/site-packages/django/contrib/admin/templatetags/admin_list.py", line 330, in results
    yield ResultList(None, items_for_result(cl, res, None))
          ^^^^^^^^^^^^^^^^^^^^^^^^^^^^^^^^^^^^^^^^^^^^^^^^^
  File "/usr/local/lib/python3.12/site-packages/django/contrib/admin/templatetags/admin_list.py", line 321, in __init__
    super().__init__(*items)
  File "/usr/local/lib/python3.12/site-packages/django/contrib/admin/templatetags/admin_list.py", line 219, in items_for_result
    f, attr, value = lookup_field(field_name, result, cl.model_admin)
                     ^^^^^^^^^^^^^^^^^^^^^^^^^^^^^^^^^^^^^^^^^^^^^^^^
  File "/usr/local/lib/python3.12/site-packages/django/contrib/admin/utils.py", line 299, in lookup_field
    value = attr(obj)
            ^^^^^^^^^
  File "/usr/local/lib/python3.12/site-packages/django/contrib/admin/options.py", line 1031, in action_checkbox
    _("Select this object for an action - {}"), str(obj)
                                                ^^^^^^^^
  File "/code/core/apps/cars/models/car.py", line 24, in __str__
    return f'car {self.date}, price {self.price}rubl'
                  ^^^^^^^^^
AttributeError: 'Car' object has no attribute 'date'
ERROR 2025-08-02 15:14:02,427 log Internal Server Error: /admin/cars/car/
Traceback (most recent call last):
  File "/usr/local/lib/python3.12/site-packages/django/db/models/options.py", line 683, in get_field
    return self.fields_map[field_name]
           ~~~~~~~~~~~~~~~^^^^^^^^^^^^
KeyError: 'action_checkbox'

During handling of the above exception, another exception occurred:

Traceback (most recent call last):
  File "/usr/local/lib/python3.12/site-packages/django/contrib/admin/utils.py", line 290, in lookup_field
    f = _get_non_gfk_field(opts, name)
        ^^^^^^^^^^^^^^^^^^^^^^^^^^^^^^
  File "/usr/local/lib/python3.12/site-packages/django/contrib/admin/utils.py", line 330, in _get_non_gfk_field
    field = opts.get_field(name)
            ^^^^^^^^^^^^^^^^^^^^
  File "/usr/local/lib/python3.12/site-packages/django/db/models/options.py", line 685, in get_field
    raise FieldDoesNotExist(
django.core.exceptions.FieldDoesNotExist: Car has no field named 'action_checkbox'

During handling of the above exception, another exception occurred:

Traceback (most recent call last):
  File "/usr/local/lib/python3.12/site-packages/asgiref/sync.py", line 489, in thread_handler
    raise exc_info[1]
  File "/usr/local/lib/python3.12/site-packages/django/core/handlers/exception.py", line 42, in inner
    response = await get_response(request)
               ^^^^^^^^^^^^^^^^^^^^^^^^^^^
  File "/usr/local/lib/python3.12/site-packages/asgiref/sync.py", line 489, in thread_handler
    raise exc_info[1]
  File "/usr/local/lib/python3.12/site-packages/django/core/handlers/base.py", line 284, in _get_response_async
    response = await sync_to_async(
               ^^^^^^^^^^^^^^^^^^^^
  File "/usr/local/lib/python3.12/site-packages/asgiref/sync.py", line 439, in __call__
    ret = await asyncio.shield(exec_coro)
          ^^^^^^^^^^^^^^^^^^^^^^^^^^^^^^^
  File "/usr/local/lib/python3.12/concurrent/futures/thread.py", line 59, in run
    result = self.fn(*self.args, **self.kwargs)
             ^^^^^^^^^^^^^^^^^^^^^^^^^^^^^^^^^^
  File "/usr/local/lib/python3.12/site-packages/asgiref/sync.py", line 493, in thread_handler
    return func(*args, **kwargs)
           ^^^^^^^^^^^^^^^^^^^^^
  File "/usr/local/lib/python3.12/site-packages/django/template/response.py", line 114, in render
    self.content = self.rendered_content
                   ^^^^^^^^^^^^^^^^^^^^^
  File "/usr/local/lib/python3.12/site-packages/django/template/response.py", line 92, in rendered_content
    return template.render(context, self._request)
           ^^^^^^^^^^^^^^^^^^^^^^^^^^^^^^^^^^^^^^^
  File "/usr/local/lib/python3.12/site-packages/django/template/backends/django.py", line 107, in render
    return self.template.render(context)
           ^^^^^^^^^^^^^^^^^^^^^^^^^^^^^
  File "/usr/local/lib/python3.12/site-packages/django/template/base.py", line 171, in render
    return self._render(context)
           ^^^^^^^^^^^^^^^^^^^^^
  File "/usr/local/lib/python3.12/site-packages/django/template/base.py", line 163, in _render
    return self.nodelist.render(context)
           ^^^^^^^^^^^^^^^^^^^^^^^^^^^^^
  File "/usr/local/lib/python3.12/site-packages/django/template/base.py", line 1016, in render
    return SafeString("".join([node.render_annotated(context) for node in self]))
                               ^^^^^^^^^^^^^^^^^^^^^^^^^^^^^^
  File "/usr/local/lib/python3.12/site-packages/django/template/base.py", line 977, in render_annotated
    return self.render(context)
           ^^^^^^^^^^^^^^^^^^^^
  File "/usr/local/lib/python3.12/site-packages/django/template/loader_tags.py", line 159, in render
    return compiled_parent._render(context)
           ^^^^^^^^^^^^^^^^^^^^^^^^^^^^^^^^
  File "/usr/local/lib/python3.12/site-packages/django/template/base.py", line 163, in _render
    return self.nodelist.render(context)
           ^^^^^^^^^^^^^^^^^^^^^^^^^^^^^
  File "/usr/local/lib/python3.12/site-packages/django/template/base.py", line 1016, in render
    return SafeString("".join([node.render_annotated(context) for node in self]))
                               ^^^^^^^^^^^^^^^^^^^^^^^^^^^^^^
  File "/usr/local/lib/python3.12/site-packages/django/template/base.py", line 977, in render_annotated
    return self.render(context)
           ^^^^^^^^^^^^^^^^^^^^
  File "/usr/local/lib/python3.12/site-packages/django/template/loader_tags.py", line 159, in render
    return compiled_parent._render(context)
           ^^^^^^^^^^^^^^^^^^^^^^^^^^^^^^^^
  File "/usr/local/lib/python3.12/site-packages/django/template/base.py", line 163, in _render
    return self.nodelist.render(context)
           ^^^^^^^^^^^^^^^^^^^^^^^^^^^^^
  File "/usr/local/lib/python3.12/site-packages/django/template/base.py", line 1016, in render
    return SafeString("".join([node.render_annotated(context) for node in self]))
                               ^^^^^^^^^^^^^^^^^^^^^^^^^^^^^^
  File "/usr/local/lib/python3.12/site-packages/django/template/base.py", line 977, in render_annotated
    return self.render(context)
           ^^^^^^^^^^^^^^^^^^^^
  File "/usr/local/lib/python3.12/site-packages/django/template/loader_tags.py", line 65, in render
    result = block.nodelist.render(context)
             ^^^^^^^^^^^^^^^^^^^^^^^^^^^^^^
  File "/usr/local/lib/python3.12/site-packages/django/template/base.py", line 1016, in render
    return SafeString("".join([node.render_annotated(context) for node in self]))
                               ^^^^^^^^^^^^^^^^^^^^^^^^^^^^^^
  File "/usr/local/lib/python3.12/site-packages/django/template/base.py", line 977, in render_annotated
    return self.render(context)
           ^^^^^^^^^^^^^^^^^^^^
  File "/usr/local/lib/python3.12/site-packages/django/template/loader_tags.py", line 65, in render
    result = block.nodelist.render(context)
             ^^^^^^^^^^^^^^^^^^^^^^^^^^^^^^
  File "/usr/local/lib/python3.12/site-packages/django/template/base.py", line 1016, in render
    return SafeString("".join([node.render_annotated(context) for node in self]))
                               ^^^^^^^^^^^^^^^^^^^^^^^^^^^^^^
  File "/usr/local/lib/python3.12/site-packages/django/template/base.py", line 977, in render_annotated
    return self.render(context)
           ^^^^^^^^^^^^^^^^^^^^
  File "/usr/local/lib/python3.12/site-packages/django/template/loader_tags.py", line 65, in render
    result = block.nodelist.render(context)
             ^^^^^^^^^^^^^^^^^^^^^^^^^^^^^^
  File "/usr/local/lib/python3.12/site-packages/django/template/base.py", line 1016, in render
    return SafeString("".join([node.render_annotated(context) for node in self]))
                               ^^^^^^^^^^^^^^^^^^^^^^^^^^^^^^
  File "/usr/local/lib/python3.12/site-packages/django/template/base.py", line 977, in render_annotated
    return self.render(context)
           ^^^^^^^^^^^^^^^^^^^^
  File "/usr/local/lib/python3.12/site-packages/django/contrib/admin/templatetags/base.py", line 45, in render
    return super().render(context)
           ^^^^^^^^^^^^^^^^^^^^^^^
  File "/usr/local/lib/python3.12/site-packages/django/template/library.py", line 359, in render
    _dict = self.func(*resolved_args, **resolved_kwargs)
            ^^^^^^^^^^^^^^^^^^^^^^^^^^^^^^^^^^^^^^^^^^^^
  File "/usr/local/lib/python3.12/site-packages/django/contrib/admin/templatetags/admin_list.py", line 354, in result_list
    "results": list(results(cl)),
               ^^^^^^^^^^^^^^^^^
  File "/usr/local/lib/python3.12/site-packages/django/contrib/admin/templatetags/admin_list.py", line 330, in results
    yield ResultList(None, items_for_result(cl, res, None))
          ^^^^^^^^^^^^^^^^^^^^^^^^^^^^^^^^^^^^^^^^^^^^^^^^^
  File "/usr/local/lib/python3.12/site-packages/django/contrib/admin/templatetags/admin_list.py", line 321, in __init__
    super().__init__(*items)
  File "/usr/local/lib/python3.12/site-packages/django/contrib/admin/templatetags/admin_list.py", line 219, in items_for_result
    f, attr, value = lookup_field(field_name, result, cl.model_admin)
                     ^^^^^^^^^^^^^^^^^^^^^^^^^^^^^^^^^^^^^^^^^^^^^^^^
  File "/usr/local/lib/python3.12/site-packages/django/contrib/admin/utils.py", line 299, in lookup_field
    value = attr(obj)
            ^^^^^^^^^
  File "/usr/local/lib/python3.12/site-packages/django/contrib/admin/options.py", line 1031, in action_checkbox
    _("Select this object for an action - {}"), str(obj)
                                                ^^^^^^^^
  File "/code/core/apps/cars/models/car.py", line 24, in __str__
    return f'car {self.year}, price {self.price}rubl'
                  ^^^^^^^^^
AttributeError: 'Car' object has no attribute 'date'
WARNING 2025-08-02 15:42:14,061 log Bad Request: /api/v1/cars/car/list/
WARNING 2025-08-02 15:42:39,859 log Bad Request: /api/v1/cars/car/list/
WARNING 2025-08-02 15:45:39,658 log Bad Request: /api/v1/cars/car/list/
WARNING 2025-08-02 17:16:28,646 log Not Found: /.well-known/appspecific/com.chrome.devtools.json
